Workbook

Sheet PROJECT NAME NOV
B1: Project Code / WO - XXXXXXXXXXXXXXXXXXXX | V1: Total Payable | W1: Retention | X1: Net Payable | AQ1: Total Payable | AR1: Retention | AS1: Net Payable | BM1: Total Payable | BN1: Retention | BO1: Net Payable | CI1: Total Payable | CJ1: Retention | CK1: Net Payable | CW1: Total Payable | CX1: Retention | CY1: Net Payable | DC1: Total Payable | DD1: Total Retention | DE1: Net Payable
B2: Project Manager : XXXXXXXXXXX | T2: Total Manpower Cost | V2: =SUM(V7:V106) -> 45762.5 | W2: =SUM(W7:W106) -> 2288.125 | X2: =V2-V4-W2 -> 43474.375 | AQ2: =SUM(AQ7:AQ106) -> 110700 | AR2: =SUM(AR7:AR106) -> 5535 | AS2: =AQ2-AR4-AR2 -> 105165 | BK2: Total Manpower Cost | BM2: =SUM(BM7:BM106) -> 386190.62 | BN2: =SUM(BN7:BN106) -> 19309.531 | BO2: =BM2-BM4-BN2 -> 366881.09 | CG2: Total Manpower Cost | CI2: =SUM(CI7:CI106) -> 425700 | CJ2: =SUM(CJ7:CJ106) -> 21285 | CK2: =CI2-CI4-CJ2 -> 404415 | CU2: Total Manpower Cost | CW2: =SUM(CW7:CW106) -> 112600 | CX2: =SUM(CX7:CX106) -> 5630 | CY2: =CW2-CW4-CX2 -> 106970 | DA2: Total Manpower Cost/Month | DC2: =SUM(V2,AQ2,BM2,CI2,CW2) -> 1080953.1 | DD2: =SUM(AR2,BN2,CJ2,CX2) -> 51759.531 | DE2: =DC2-DC4-DD2 -> 973193.59
B3: Site Supervisor : XXXXXXXXXXX
F4: Saturday | H4: Sunday | J4: Monday | L4: Tuesday | N4: Wednesday | P4: Thursday | T4: Advance | V4: 0 | Y4: Friday | AA4: Saturday | AC4: Sunday | AE4: Monday | AG4: Tuesday | AI4: Wednesday | AK4: Thursday | AQ4: Advance | AR4: 0 | AU4: Friday | AW4: Saturday | AY4: Sunday | BA4: Monday | BC4: Tuesday | BE4: Wednesday | BG4: Thursday | BK4: Advance | BM4: 0 | BQ4: Friday | BS4: Saturday | BU4: Sunday | BW4: Monday | BY4: Tuesday | CA4: Wednesday | CC4: Thursday | CG4: Advance | CI4: 0 | CM4: Friday | CO4: Saturday | CQ4: Sunday | CU4: Advance | CW4: 0 | DA4: Advance | DC4: 56000
B5: Contractor / Vendor | C5: Category | D5: Labour Id | E5: Labour Name | F5: 45962 | H5: 45963 | J5: 45964 | L5: 45965 | N5: 45966 | P5: 45967 | R5: Total Hours | S5: OT Hours | T5: Hourly Rate | U5: Daily Rate | V5: Total Payable | W5: Retention @ 5% | X5: Net Payable | Y5: 45968 | AA5: 45969 | AC5: 45970 | AE5: 45971 | AG5: 45972 | AI5: 45973 | AK5: 45974 | AM5: Hourly Rate | AN5: Daily Rate | AO5: Total Hours | AP5: OT Hours | AQ5: Total Payable | AR5: Retention @ 5% | AS5: Net Payable | AU5: 45975 | AW5: 45976 | AY5: 45977 | BA5: 45978 | BC5: 45979 | BE5: 45980 | BG5: 45981 | BI5: Total Hours | BJ5: OT Hours | BK5: Hourly Rate | BL5: Daily Rate | BM5: Total Payable | BN5: Retention @ 5% | BO5: Net Payable | BQ5: 45982 | BS5: 45983 | BU5: 45984 | BW5: 45985 | BY5: 45986 | CA5: 45987 | CC5: 45988 | CE5: Total Hours | CF5: OT Hours | CG5: Hourly Rate | CH5: Daily Rate | CI5: Total Payable | CJ5: Retention @ 5% | CK5: Net Payable | CM5: 45989 | CO5: 45990 | CQ5: 45991 | CS5: Total Hours | CT5: OT Hours | CU5: Hourly Rate | CV5: Daily Rate | CW5: Total Payable | CX5: Retention @ 5% | CY5: Net Payable
F6: Duty Hours | G6: OT Hours | H6: Duty Hours | I6: OT Hours | J6: Duty Hours | K6: OT Hours | L6: Duty Hours | M6: OT Hours | N6: Duty Hours | O6: OT Hours | P6: Duty Hours | Q6: OT Hours | Y6: Duty Hours | Z6: OT Hours | AA6: Duty Hours | AB6: OT Hours | AC6: Duty Hours | AD6: OT Hours | AE6: Duty Hours | AF6: OT Hours | AG6: Duty Hours | AH6: OT Hours | AI6: Duty Hours | AJ6: OT Hours | AK6: Duty Hours | AL6: OT Hours | AU6: Duty Hours | AV6: OT Hours | AW6: Duty Hours | AX6: OT Hours | AY6: Duty Hours | AZ6: OT Hours | BA6: Duty Hours | BB6: OT Hours | BC6: Duty Hours | BD6: OT Hours | BE6: Duty Hours | BF6: OT Hours | BG6: Duty Hours | BH6: OT Hours | BQ6: Duty Hours | BR6: OT Hours | BS6: Duty Hours | BT6: OT Hours | BU6: Duty Hours | BV6: OT Hours | BW6: Duty Hours | BX6: OT Hours | BY6: Duty Hours | BZ6: OT Hours | CA6: Duty Hours | CB6: OT Hours | CC6: Duty Hours | CD6: OT Hours | CM6: Duty Hours | CN6: OT Hours | CO6: Duty Hours | CP6: OT Hours | CQ6: Duty Hours | CR6: OT Hours | DH6: Helper
B7: Ramakanth | C7: Carpenter | D7: Labour-001 | E7: Ramakanth | R7: =SUM(F7,H7,J7,L7,N7,P7) -> 0 | S7: =SUM(G7,I7,K7,M7,O7,Q7) -> 0 | T7: =IFERROR(INDEX(Settings!$F:$F, MATCH('PROJECT NAME NOV'!$B7 & "-" & 'PROJECT NAME NOV'!$C7, Settings!$H:$H,0)), "") -> 106.25 | U7: =IFERROR(INDEX(Settings!$G:$G, MATCH('PROJECT NAME NOV'!$B7 & "-" & 'PROJECT NAME NOV'!$C7, Settings!$H:$H, 0)), "") -> 850 | V7: =(R7*T7)+(S7*T7) -> 0 | W7: =V7*5% -> 0 | X7: =V7-W7 -> 0 | Y7: 8 | Z7: 0 | AA7: 8 | AB7: 2 | AC7: 8 | AD7: 0 | AE7: 8 | AF7: 2 | AG7: 8 | AH7: 2 | AI7: 8 | AJ7: 2 | AK7: 8 | AL7: 2 | AM7: =IFERROR(INDEX(Settings!$F:$F, MATCH('PROJECT NAME NOV'!$B7 & "-" & 'PROJECT NAME NOV'!$C7, Settings!$H:$H,0)), "") -> 106.25 | AN7: =IFERROR(INDEX(Settings!$G:$G, MATCH('PROJECT NAME NOV'!$B7 & "-" & 'PROJECT NAME NOV'!$C7, Settings!$H:$H, 0)), "") -> 850 | AO7: =SUM(Y7,AA7,AC7,AE7,AG7,AI7,AK7) -> 56 | AP7: =SUM(Z7,AB7,AD7,AF7,AH7,AJ7,AL7) -> 10 | AQ7: =(AO7*AM7)+(AP7*AM7) -> 7012.5 | AR7: =AQ7*5% -> 350.625 | AS7: =AQ7-AR7 -> 6661.875 | AU7: 8 | AV7: 2 | AW7: 8 | AX7: 4 | AY7: 8 | AZ7: 0 | BA7: 8 | BB7: 4 | BC7: 8 | BD7: 4 | BE7: 8 | BF7: 0 | BG7: 8 | BH7: 4 | BI7: =SUM(AU7,AW7,AY7,BA7,BC7,BE7,BG7) -> 56 | BJ7: =SUM(AV7,AX7,AZ7,BB7,BD7,BF7,BH7) -> 18 | BK7: =IFERROR(INDEX(Settings!$F:$F, MATCH('PROJECT NAME NOV'!$B7 & "-" & 'PROJECT NAME NOV'!$C7, Settings!$H:$H,0)), "") -> 106.25 | BL7: =IFERROR(INDEX(Settings!$G:$G, MATCH('PROJECT NAME NOV'!$B7 & "-" & 'PROJECT NAME NOV'!$C7, Settings!$H:$H, 0)), "") -> 850 | BM7: =(BI7*BK7)+(BJ7*BK7) -> 7862.5 | BN7: =BM7*5% -> 393.125 | BO7: =BM7-BN7 -> 7469.375 | BQ7: 8 | BR7: 2 | BS7: 8 | BT7: 2 | BU7: 8 | BV7: 0 | BW7: 8 | BX7: 2 | BY7: 8 | BZ7: 2 | CA7: 8 | CB7: 2 | CC7: 8 | CE7: =SUM(BQ7,BS7,BU7,BW7,BY7,CA7,CC7) -> 56 | CF7: =SUM(BR7,BT7,BV7,BX7,BZ7,CB7,CD7) -> 10 | CG7: =IFERROR(INDEX(Settings!$F:$F, MATCH('PROJECT NAME NOV'!$B7 & "-" & 'PROJECT NAME NOV'!$C7, Settings!$H:$H,0)), "") -> 106.25 | CH7: =IFERROR(INDEX(Settings!$G:$G, MATCH('PROJECT NAME NOV'!$B7 & "-" & 'PROJECT NAME NOV'!$C7, Settings!$H:$H, 0)), "") -> 850 | CI7: =(CE7*CG7)+(CF7*CG7) -> 7012.5 | CJ7: =CI7*5% -> 350.625 | CK7: =CI7-CJ7 -> 6661.875 | CM7: 8 | CN7: 4 | CO7: 8 | CP7: 4 | CS7: =SUM(CM7,CO7,CQ7) -> 16 | CT7: =SUM(CN7,CP7,CR7) -> 8 | CU7: =IFERROR(INDEX(Settings!$F:$F, MATCH('PROJECT NAME NOV'!$B7 & "-" & 'PROJECT NAME NOV'!$C7, Settings!$H:$H,0)), "") -> 106.25 | CV7: =IFERROR(INDEX(Settings!$G:$G, MATCH('PROJECT NAME NOV'!$B7 & "-" & 'PROJECT NAME NOV'!$C7, Settings!$H:$H, 0)), "") -> 850 | CW7: =(CU7*CS7)+(CT7*CU7) -> 2550 | CX7: =CW7*5% -> 127.5 | CY7: =CW7-CX7 -> 2422.5 | DH7: ='Billable Till Date'!B3 & "-" & 'Billable Till Date'!C3 -> L - Reinf Steel Work-MT
B8: Ramakanth | C8: Carpenter | D8: Labour-002 | E8: Ram Kishor | R8: =SUM(F8,H8,J8,L8,N8,P8) -> 0 | S8: =SUM(G8,I8,K8,M8,O8,Q8) -> 0 | T8: =IFERROR(INDEX(Settings!$F:$F, MATCH('PROJECT NAME NOV'!$B8 & "-" & 'PROJECT NAME NOV'!$C8, Settings!$H:$H,0)), "") -> 106.25 | U8: =IFERROR(INDEX(Settings!$G:$G, MATCH('PROJECT NAME NOV'!$B8 & "-" & 'PROJECT NAME NOV'!$C8, Settings!$H:$H, 0)), "") -> 850 | V8: =(R8*T8)+(S8*T8) -> 0 | W8: =V8*5% -> 0 | X8: =V8-W8 -> 0 | Y8: 8 | Z8: 0 | AA8: 8 | AB8: 2 | AC8: 8 | AD8: 0 | AE8: 8 | AF8: 2 | AG8: 8 | AH8: 2 | AI8: 0 | AJ8: 0 | AK8: 0 | AL8: 0 | AM8: =IFERROR(INDEX(Settings!$F:$F, MATCH('PROJECT NAME NOV'!$B8 & "-" & 'PROJECT NAME NOV'!$C8, Settings!$H:$H,0)), "") -> 106.25 | AN8: =IFERROR(INDEX(Settings!$G:$G, MATCH('PROJECT NAME NOV'!$B8 & "-" & 'PROJECT NAME NOV'!$C8, Settings!$H:$H, 0)), "") -> 850 | AO8: =SUM(Y8,AA8,AC8,AE8,AG8,AI8,AK8) -> 40 | AP8: =SUM(Z8,AB8,AD8,AF8,AH8,AJ8,AL8) -> 6 | AQ8: =(AO8*AM8)+(AP8*AM8) -> 4887.5 | AR8: =AQ8*5% -> 244.375 | AS8: =AQ8-AR8 -> 4643.125 | AU8: 0 | AV8: 0 | AW8: 0 | AX8: 0 | AY8: 0 | AZ8: 0 | BA8: 0 | BB8: 0 | BC8: 0 | BD8: 0 | BE8: 0 | BF8: 0 | BG8: 0 | BH8: 0 | BI8: =SUM(AU8,AW8,AY8,BA8,BC8,BE8,BG8) -> 0 | BJ8: =SUM(AV8,AX8,AZ8,BB8,BD8,BF8,BH8) -> 0 | BK8: =IFERROR(INDEX(Settings!$F:$F, MATCH('PROJECT NAME NOV'!$B8 & "-" & 'PROJECT NAME NOV'!$C8, Settings!$H:$H,0)), "") -> 106.25 | BL8: =IFERROR(INDEX(Settings!$G:$G, MATCH('PROJECT NAME NOV'!$B8 & "-" & 'PROJECT NAME NOV'!$C8, Settings!$H:$H, 0)), "") -> 850 | BM8: =(BI8*BK8)+(BJ8*BK8) -> 0 | BN8: =BM8*5% -> 0 | BO8: =BM8-BN8 -> 0 | BQ8: 0 | BR8: 0 | BS8: 0 | BT8: 0 | BU8: 0 | BV8: 0 | BW8: 0 | BX8: 0 | BY8: 0 | BZ8: 0 | CA8: 0 | CB8: 0 | CC8: 0 | CD8: 0 | CE8: =SUM(BQ8,BS8,BU8,BW8,BY8,CA8,CC8) -> 0 | CF8: =SUM(BR8,BT8,BV8,BX8,BZ8,CB8,CD8) -> 0 | CG8: =IFERROR(INDEX(Settings!$F:$F, MATCH('PROJECT NAME NOV'!$B8 & "-" & 'PROJECT NAME NOV'!$C8, Settings!$H:$H,0)), "") -> 106.25 | CH8: =IFERROR(INDEX(Settings!$G:$G, MATCH('PROJECT NAME NOV'!$B8 & "-" & 'PROJECT NAME NOV'!$C8, Settings!$H:$H, 0)), "") -> 850 | CI8: =(CE8*CG8)+(CF8*CG8) -> 0 | CJ8: =CI8*5% -> 0 | CK8: =CI8-CJ8 -> 0 | CM8: 0 | CS8: =SUM(CM8,CO8,CQ8) -> 0 | CT8: =SUM(CN8,CP8,CR8) -> 0 | CU8: =IFERROR(INDEX(Settings!$F:$F, MATCH('PROJECT NAME NOV'!$B8 & "-" & 'PROJECT NAME NOV'!$C8, Settings!$H:$H,0)), "") -> 106.25 | CV8: =IFERROR(INDEX(Settings!$G:$G, MATCH('PROJECT NAME NOV'!$B8 & "-" & 'PROJECT NAME NOV'!$C8, Settings!$H:$H, 0)), "") -> 850 | CW8: =(CU8*CS8)+(CT8*CU8) -> 0 | CX8: =CW8*5% -> 0 | CY8: =CW8-CX8 -> 0 | DH8: ='Billable Till Date'!B4 & "-" & 'Billable Till Date'!C4 -> L - Shuttering-Footings in Sub Str (Foundation)-Sqm
B9: Ramakanth | C9: Carpenter | D9: Labour-003 | E9: Hiraman Saurat | R9: =SUM(F9,H9,J9,L9,N9,P9) -> 0 | S9: =SUM(G9,I9,K9,M9,O9,Q9) -> 0 | T9: =IFERROR(INDEX(Settings!$F:$F, MATCH('PROJECT NAME NOV'!$B9 & "-" & 'PROJECT NAME NOV'!$C9, Settings!$H:$H,0)), "") -> 106.25 | U9: =IFERROR(INDEX(Settings!$G:$G, MATCH('PROJECT NAME NOV'!$B9 & "-" & 'PROJECT NAME NOV'!$C9, Settings!$H:$H, 0)), "") -> 850 | V9: =(R9*T9)+(S9*T9) -> 0 | W9: =V9*5% -> 0 | X9: =V9-W9 -> 0 | Y9: 8 | Z9: 0 | AA9: 8 | AB9: 2 | AC9: 8 | AD9: 0 | AE9: 8 | AF9: 2 | AG9: 8 | AH9: 2 | AI9: 8 | AJ9: 2 | AK9: 8 | AL9: 2 | AM9: =IFERROR(INDEX(Settings!$F:$F, MATCH('PROJECT NAME NOV'!$B9 & "-" & 'PROJECT NAME NOV'!$C9, Settings!$H:$H,0)), "") -> 106.25 | AN9: =IFERROR(INDEX(Settings!$G:$G, MATCH('PROJECT NAME NOV'!$B9 & "-" & 'PROJECT NAME NOV'!$C9, Settings!$H:$H, 0)), "") -> 850 | AO9: =SUM(Y9,AA9,AC9,AE9,AG9,AI9,AK9) -> 56 | AP9: =SUM(Z9,AB9,AD9,AF9,AH9,AJ9,AL9) -> 10 | AQ9: =(AO9*AM9)+(AP9*AM9) -> 7012.5 | AR9: =AQ9*5% -> 350.625 | AS9: =AQ9-AR9 -> 6661.875 | AU9: 8 | AV9: 2 | AW9: 8 | AX9: 4 | AY9: 8 | AZ9: 0 | BA9: 8 | BB9: 4 | BC9: 8 | BD9: 4 | BE9: 8 | BF9: 0 | BG9: 8 | BH9: 4 | BI9: =SUM(AU9,AW9,AY9,BA9,BC9,BE9,BG9) -> 56 | BJ9: =SUM(AV9,AX9,AZ9,BB9,BD9,BF9,BH9) -> 18 | BK9: =IFERROR(INDEX(Settings!$F:$F, MATCH('PROJECT NAME NOV'!$B9 & "-" & 'PROJECT NAME NOV'!$C9, Settings!$H:$H,0)), "") -> 106.25 | BL9: =IFERROR(INDEX(Settings!$G:$G, MATCH('PROJECT NAME NOV'!$B9 & "-" & 'PROJECT NAME NOV'!$C9, Settings!$H:$H, 0)), "") -> 850 | BM9: =(BI9*BK9)+(BJ9*BK9) -> 7862.5 | BN9: =BM9*5% -> 393.125 | BO9: =BM9-BN9 -> 7469.375 | BQ9: 8 | BR9: 2 | BS9: 8 | BT9: 2 | BU9: 8 | BV9: 0 | BW9: 8 | BX9: 2 | BY9: 8 | BZ9: 2 | CA9: 8 | CB9: 0 | CC9: 0 | CE9: =SUM(BQ9,BS9,BU9,BW9,BY9,CA9,CC9) -> 48 | CF9: =SUM(BR9,BT9,BV9,BX9,BZ9,CB9,CD9) -> 8 | CG9: =IFERROR(INDEX(Settings!$F:$F, MATCH('PROJECT NAME NOV'!$B9 & "-" & 'PROJECT NAME NOV'!$C9, Settings!$H:$H,0)), "") -> 106.25 | CH9: =IFERROR(INDEX(Settings!$G:$G, MATCH('PROJECT NAME NOV'!$B9 & "-" & 'PROJECT NAME NOV'!$C9, Settings!$H:$H, 0)), "") -> 850 | CI9: =(CE9*CG9)+(CF9*CG9) -> 5950 | CJ9: =CI9*5% -> 297.5 | CK9: =CI9-CJ9 -> 5652.5 | CM9: 0 | CS9: =SUM(CM9,CO9,CQ9) -> 0 | CT9: =SUM(CN9,CP9,CR9) -> 0 | CU9: =IFERROR(INDEX(Settings!$F:$F, MATCH('PROJECT NAME NOV'!$B9 & "-" & 'PROJECT NAME NOV'!$C9, Settings!$H:$H,0)), "") -> 106.25 | CV9: =IFERROR(INDEX(Settings!$G:$G, MATCH('PROJECT NAME NOV'!$B9 & "-" & 'PROJECT NAME NOV'!$C9, Settings!$H:$H, 0)), "") -> 850 | CW9: =(CU9*CS9)+(CT9*CU9) -> 0 | CX9: =CW9*5% -> 0 | CY9: =CW9-CX9 -> 0 | DH9: ='Billable Till Date'!B5 & "-" & 'Billable Till Date'!C5 -> L - Reinforcement Work (Site Infra)-MT
B10: Ramakanth | C10: Carpenter | D10: Labour-004 | E10: Vikram Adivasi | R10: =SUM(F10,H10,J10,L10,N10,P10) -> 0 | S10: =SUM(G10,I10,K10,M10,O10,Q10) -> 0 | T10: =IFERROR(INDEX(Settings!$F:$F, MATCH('PROJECT NAME NOV'!$B10 & "-" & 'PROJECT NAME NOV'!$C10, Settings!$H:$H,0)), "") -> 106.25 | U10: =IFERROR(INDEX(Settings!$G:$G, MATCH('PROJECT NAME NOV'!$B10 & "-" & 'PROJECT NAME NOV'!$C10, Settings!$H:$H, 0)), "") -> 850 | V10: =(R10*T10)+(S10*T10) -> 0 | W10: =V10*5% -> 0 | X10: =V10-W10 -> 0 | Y10: 8 | Z10: 0 | AA10: 8 | AB10: 2 | AC10: 8 | AD10: 0 | AE10: 0 | AF10: 0 | AG10: 0 | AH10: 0 | AI10: 0 | AJ10: 0 | AK10: 0 | AL10: 0 | AM10: =IFERROR(INDEX(Settings!$F:$F, MATCH('PROJECT NAME NOV'!$B10 & "-" & 'PROJECT NAME NOV'!$C10, Settings!$H:$H,0)), "") -> 106.25 | AN10: =IFERROR(INDEX(Settings!$G:$G, MATCH('PROJECT NAME NOV'!$B10 & "-" & 'PROJECT NAME NOV'!$C10, Settings!$H:$H, 0)), "") -> 850 | AO10: =SUM(Y10,AA10,AC10,AE10,AG10,AI10,AK10) -> 24 | AP10: =SUM(Z10,AB10,AD10,AF10,AH10,AJ10,AL10) -> 2 | AQ10: =(AO10*AM10)+(AP10*AM10) -> 2762.5 | AR10: =AQ10*5% -> 138.125 | AS10: =AQ10-AR10 -> 2624.375 | AU10: 0 | AV10: 0 | AW10: 0 | AX10: 0 | AY10: 0 | AZ10: 0 | BA10: 0 | BB10: 0 | BC10: 0 | BD10: 0 | BE10: 0 | BF10: 0 | BG10: 0 | BH10: 0 | BI10: =SUM(AU10,AW10,AY10,BA10,BC10,BE10,BG10) -> 0 | BJ10: =SUM(AV10,AX10,AZ10,BB10,BD10,BF10,BH10) -> 0 | BK10: =IFERROR(INDEX(Settings!$F:$F, MATCH('PROJECT NAME NOV'!$B10 & "-" & 'PROJECT NAME NOV'!$C10, Settings!$H:$H,0)), "") -> 106.25 | BL10: =IFERROR(INDEX(Settings!$G:$G, MATCH('PROJECT NAME NOV'!$B10 & "-" & 'PROJECT NAME NOV'!$C10, Settings!$H:$H, 0)), "") -> 850 | BM10: =(BI10*BK10)+(BJ10*BK10) -> 0 | BN10: =BM10*5% -> 0 | BO10: =BM10-BN10 -> 0 | BQ10: 0 | BR10: 0 | BS10: 0 | BT10: 0 | BU10: 0 | BV10: 0 | BW10: 0 | BX10: 0 | BY10: 0 | BZ10: 0 | CA10: 0 | CB10: 0 | CC10: 0 | CD10: 0 | CE10: =SUM(BQ10,BS10,BU10,BW10,BY10,CA10,CC10) -> 0 | CF10: =SUM(BR10,BT10,BV10,BX10,BZ10,CB10,CD10) -> 0 | CG10: =IFERROR(INDEX(Settings!$F:$F, MATCH('PROJECT NAME NOV'!$B10 & "-" & 'PROJECT NAME NOV'!$C10, Settings!$H:$H,0)), "") -> 106.25 | CH10: =IFERROR(INDEX(Settings!$G:$G, MATCH('PROJECT NAME NOV'!$B10 & "-" & 'PROJECT NAME NOV'!$C10, Settings!$H:$H, 0)), "") -> 850 | CI10: =(CE10*CG10)+(CF10*CG10) -> 0 | CJ10: =CI10*5% -> 0 | CK10: =CI10-CJ10 -> 0 | CM10: 8 | CN10: 4 | CO10: 8 | CP10: 4 | CS10: =SUM(CM10,CO10,CQ10) -> 16 | CT10: =SUM(CN10,CP10,CR10) -> 8 | CU10: =IFERROR(INDEX(Settings!$F:$F, MATCH('PROJECT NAME NOV'!$B10 & "-" & 'PROJECT NAME NOV'!$C10, Settings!$H:$H,0)), "") -> 106.25 | CV10: =IFERROR(INDEX(Settings!$G:$G, MATCH('PROJECT NAME NOV'!$B10 & "-" & 'PROJECT NAME NOV'!$C10, Settings!$H:$H, 0)), "") -> 850 | CW10: =(CU10*CS10)+(CT10*CU10) -> 2550 | CX10: =CW10*5% -> 127.5 | CY10: =CW10-CX10 -> 2422.5 | DH10: ='Billable Till Date'!B6 & "-" & 'Billable Till Date'!C6 -> L - Shuttering Work (Site Infra)-Sqm
B11: Ramakanth | C11: Carpenter | D11: Labour-005 | E11: buddan Kori | R11: =SUM(F11,H11,J11,L11,N11,P11) -> 0 | S11: =SUM(G11,I11,K11,M11,O11,Q11) -> 0 | T11: =IFERROR(INDEX(Settings!$F:$F, MATCH('PROJECT NAME NOV'!$B11 & "-" & 'PROJECT NAME NOV'!$C11, Settings!$H:$H,0)), "") -> 106.25 | U11: =IFERROR(INDEX(Settings!$G:$G, MATCH('PROJECT NAME NOV'!$B11 & "-" & 'PROJECT NAME NOV'!$C11, Settings!$H:$H, 0)), "") -> 850 | V11: =(R11*T11)+(S11*T11) -> 0 | W11: =V11*5% -> 0 | X11: =V11-W11 -> 0 | Y11: 8 | Z11: 0 | AA11: 8 | AB11: 2 | AC11: 8 | AD11: 0 | AE11: 8 | AF11: 2 | AG11: 8 | AH11: 2 | AI11: 8 | AJ11: 2 | AK11: 8 | AL11: 2 | AM11: =IFERROR(INDEX(Settings!$F:$F, MATCH('PROJECT NAME NOV'!$B11 & "-" & 'PROJECT NAME NOV'!$C11, Settings!$H:$H,0)), "") -> 106.25 | AN11: =IFERROR(INDEX(Settings!$G:$G, MATCH('PROJECT NAME NOV'!$B11 & "-" & 'PROJECT NAME NOV'!$C11, Settings!$H:$H, 0)), "") -> 850 | AO11: =SUM(Y11,AA11,AC11,AE11,AG11,AI11,AK11) -> 56 | AP11: =SUM(Z11,AB11,AD11,AF11,AH11,AJ11,AL11) -> 10 | AQ11: =(AO11*AM11)+(AP11*AM11) -> 7012.5 | AR11: =AQ11*5% -> 350.625 | AS11: =AQ11-AR11 -> 6661.875 | AU11: 8 | AV11: 2 | AW11: 8 | AX11: 4 | AY11: 8 | AZ11: 0 | BA11: 8 | BB11: 4 | BC11: 8 | BD11: 4 | BE11: 8 | BF11: 0 | BG11: 8 | BH11: 4 | BI11: =SUM(AU11,AW11,AY11,BA11,BC11,BE11,BG11) -> 56 | BJ11: =SUM(AV11,AX11,AZ11,BB11,BD11,BF11,BH11) -> 18 | BK11: =IFERROR(INDEX(Settings!$F:$F, MATCH('PROJECT NAME NOV'!$B11 & "-" & 'PROJECT NAME NOV'!$C11, Settings!$H:$H,0)), "") -> 106.25 | BL11: =IFERROR(INDEX(Settings!$G:$G, MATCH('PROJECT NAME NOV'!$B11 & "-" & 'PROJECT NAME NOV'!$C11, Settings!$H:$H, 0)), "") -> 850 | BM11: =(BI11*BK11)+(BJ11*BK11) -> 7862.5 | BN11: =BM11*5% -> 393.125 | BO11: =BM11-BN11 -> 7469.375 | BQ11: 8 | BR11: 2 | BS11: 8 | BT11: 2 | BU11: 8 | BV11: 0 | BW11: 8 | BX11: 2 | BY11: 8 | BZ11: 2 | CA11: 8 | CB11: 0 | CC11: 0 | CE11: =SUM(BQ11,BS11,BU11,BW11,BY11,CA11,CC11) -> 48 | CF11: =SUM(BR11,BT11,BV11,BX11,BZ11,CB11,CD11) -> 8 | CG11: =IFERROR(INDEX(Settings!$F:$F, MATCH('PROJECT NAME NOV'!$B11 & "-" & 'PROJECT NAME NOV'!$C11, Settings!$H:$H,0)), "") -> 106.25 | CH11: =IFERROR(INDEX(Settings!$G:$G, MATCH('PROJECT NAME NOV'!$B11 & "-" & 'PROJECT NAME NOV'!$C11, Settings!$H:$H, 0)), "") -> 850 | CI11: =(CE11*CG11)+(CF11*CG11) -> 5950 | CJ11: =CI11*5% -> 297.5 | CK11: =CI11-CJ11 -> 5652.5 | CM11: 0 | CS11: =SUM(CM11,CO11,CQ11) -> 0 | CT11: =SUM(CN11,CP11,CR11) -> 0 | CU11: =IFERROR(INDEX(Settings!$F:$F, MATCH('PROJECT NAME NOV'!$B11 & "-" & 'PROJECT NAME NOV'!$C11, Settings!$H:$H,0)), "") -> 106.25 | CV11: =IFERROR(INDEX(Settings!$G:$G, MATCH('PROJECT NAME NOV'!$B11 & "-" & 'PROJECT NAME NOV'!$C11, Settings!$H:$H, 0)), "") -> 850 | CW11: =(CU11*CS11)+(CT11*CU11) -> 0 | CX11: =CW11*5% -> 0 | CY11: =CW11-CX11 -> 0 | DH11: ='Billable Till Date'!B7 & "-" & 'Billable Till Date'!C7 -> Task/Activity-Unit Type
B12: Ramakanth | C12: Carpenter | D12: Labour-006 | E12: Dhiraj Kori | R12: =SUM(F12,H12,J12,L12,N12,P12) -> 0 | S12: =SUM(G12,I12,K12,M12,O12,Q12) -> 0 | T12: =IFERROR(INDEX(Settings!$F:$F, MATCH('PROJECT NAME NOV'!$B12 & "-" & 'PROJECT NAME NOV'!$C12, Settings!$H:$H,0)), "") -> 106.25 | U12: =IFERROR(INDEX(Settings!$G:$G, MATCH('PROJECT NAME NOV'!$B12 & "-" & 'PROJECT NAME NOV'!$C12, Settings!$H:$H, 0)), "") -> 850 | V12: =(R12*T12)+(S12*T12) -> 0 | W12: =V12*5% -> 0 | X12: =V12-W12 -> 0 | Y12: 8 | Z12: 0 | AA12: 8 | AB12: 2 | AC12: 8 | AD12: 0 | AE12: 8 | AF12: 2 | AG12: 8 | AH12: 2 | AI12: 8 | AJ12: 2 | AK12: 8 | AL12: 2 | AM12: =IFERROR(INDEX(Settings!$F:$F, MATCH('PROJECT NAME NOV'!$B12 & "-" & 'PROJECT NAME NOV'!$C12, Settings!$H:$H,0)), "") -> 106.25 | AN12: =IFERROR(INDEX(Settings!$G:$G, MATCH('PROJECT NAME NOV'!$B12 & "-" & 'PROJECT NAME NOV'!$C12, Settings!$H:$H, 0)), "") -> 850 | AO12: =SUM(Y12,AA12,AC12,AE12,AG12,AI12,AK12) -> 56 | AP12: =SUM(Z12,AB12,AD12,AF12,AH12,AJ12,AL12) -> 10 | AQ12: =(AO12*AM12)+(AP12*AM12) -> 7012.5 | AR12: =AQ12*5% -> 350.625 | AS12: =AQ12-AR12 -> 6661.875 | AU12: 8 | AV12: 2 | AW12: 8 | AX12: 4 | AY12: 8 | AZ12: 0 | BA12: 8 | BB12: 4 | BC12: 8 | BD12: 4 | BE12: 8 | BF12: 0 | BG12: 8 | BH12: 4 | BI12: =SUM(AU12,AW12,AY12,BA12,BC12,BE12,BG12) -> 56 | BJ12: =SUM(AV12,AX12,AZ12,BB12,BD12,BF12,BH12) -> 18 | BK12: =IFERROR(INDEX(Settings!$F:$F, MATCH('PROJECT NAME NOV'!$B12 & "-" & 'PROJECT NAME NOV'!$C12, Settings!$H:$H,0)), "") -> 106.25 | BL12: =IFERROR(INDEX(Settings!$G:$G, MATCH('PROJECT NAME NOV'!$B12 & "-" & 'PROJECT NAME NOV'!$C12, Settings!$H:$H, 0)), "") -> 850 | BM12: =(BI12*BK12)+(BJ12*BK12) -> 7862.5 | BN12: =BM12*5% -> 393.125 | BO12: =BM12-BN12 -> 7469.375 | BQ12: 8 | BR12: 2 | BS12: 8 | BT12: 2 | BU12: 8 | BV12: 0 | BW12: 8 | BX12: 2 | BY12: 8 | BZ12: 2 | CA12: 8 | CB12: 2 | CC12: 8 | CE12: =SUM(BQ12,BS12,BU12,BW12,BY12,CA12,CC12) -> 56 | CF12: =SUM(BR12,BT12,BV12,BX12,BZ12,CB12,CD12) -> 10 | CG12: =IFERROR(INDEX(Settings!$F:$F, MATCH('PROJECT NAME NOV'!$B12 & "-" & 'PROJECT NAME NOV'!$C12, Settings!$H:$H,0)), "") -> 106.25 | CH12: =IFERROR(INDEX(Settings!$G:$G, MATCH('PROJECT NAME NOV'!$B12 & "-" & 'PROJECT NAME NOV'!$C12, Settings!$H:$H, 0)), "") -> 850 | CI12: =(CE12*CG12)+(CF12*CG12) -> 7012.5 | CJ12: =CI12*5% -> 350.625 | CK12: =CI12-CJ12 -> 6661.875 | CM12: 8 | CN12: 4 | CO12: 8 | CP12: 4 | CS12: =SUM(CM12,CO12,CQ12) -> 16 | CT12: =SUM(CN12,CP12,CR12) -> 8 | CU12: =IFERROR(INDEX(Settings!$F:$F, MATCH('PROJECT NAME NOV'!$B12 & "-" & 'PROJECT NAME NOV'!$C12, Settings!$H:$H,0)), "") -> 106.25 | CV12: =IFERROR(INDEX(Settings!$G:$G, MATCH('PROJECT NAME NOV'!$B12 & "-" & 'PROJECT NAME NOV'!$C12, Settings!$H:$H, 0)), "") -> 850 | CW12: =(CU12*CS12)+(CT12*CU12) -> 2550 | CX12: =CW12*5% -> 127.5 | CY12: =CW12-CX12 -> 2422.5 | DH12: ='Billable Till Date'!B8 & "-" & 'Billable Till Date'!C8 -> Task/Activity-Unit Type
B13: Ramakanth | C13: Carpenter | D13: Labour-007 | E13: Pavan Kumar | R13: =SUM(F13,H13,J13,L13,N13,P13) -> 0 | S13: =SUM(G13,I13,K13,M13,O13,Q13) -> 0 | T13: =IFERROR(INDEX(Settings!$F:$F, MATCH('PROJECT NAME NOV'!$B13 & "-" & 'PROJECT NAME NOV'!$C13, Settings!$H:$H,0)), "") -> 106.25 | U13: =IFERROR(INDEX(Settings!$G:$G, MATCH('PROJECT NAME NOV'!$B13 & "-" & 'PROJECT NAME NOV'!$C13, Settings!$H:$H, 0)), "") -> 850 | V13: =(R13*T13)+(S13*T13) -> 0 | W13: =V13*5% -> 0 | X13: =V13-W13 -> 0 | Y13: 8 | Z13: 0 | AA13: 8 | AB13: 2 | AC13: 8 | AD13: 0 | AE13: 8 | AF13: 2 | AG13: 8 | AH13: 2 | AI13: 0 | AJ13: 0 | AK13: 8 | AL13: 2 | AM13: =IFERROR(INDEX(Settings!$F:$F, MATCH('PROJECT NAME NOV'!$B13 & "-" & 'PROJECT NAME NOV'!$C13, Settings!$H:$H,0)), "") -> 106.25 | AN13: =IFERROR(INDEX(Settings!$G:$G, MATCH('PROJECT NAME NOV'!$B13 & "-" & 'PROJECT NAME NOV'!$C13, Settings!$H:$H, 0)), "") -> 850 | AO13: =SUM(Y13,AA13,AC13,AE13,AG13,AI13,AK13) -> 48 | AP13: =SUM(Z13,AB13,AD13,AF13,AH13,AJ13,AL13) -> 8 | AQ13: =(AO13*AM13)+(AP13*AM13) -> 5950 | AR13: =AQ13*5% -> 297.5 | AS13: =AQ13-AR13 -> 5652.5 | AU13: 8 | AV13: 2 | AW13: 8 | AX13: 4 | AY13: 8 | AZ13: 0 | BA13: 8 | BB13: 4 | BC13: 8 | BD13: 4 | BE13: 8 | BF13: 0 | BG13: 8 | BH13: 4 | BI13: =SUM(AU13,AW13,AY13,BA13,BC13,BE13,BG13) -> 56 | BJ13: =SUM(AV13,AX13,AZ13,BB13,BD13,BF13,BH13) -> 18 | BK13: =IFERROR(INDEX(Settings!$F:$F, MATCH('PROJECT NAME NOV'!$B13 & "-" & 'PROJECT NAME NOV'!$C13, Settings!$H:$H,0)), "") -> 106.25 | BL13: =IFERROR(INDEX(Settings!$G:$G, MATCH('PROJECT NAME NOV'!$B13 & "-" & 'PROJECT NAME NOV'!$C13, Settings!$H:$H, 0)), "") -> 850 | BM13: =(BI13*BK13)+(BJ13*BK13) -> 7862.5 | BN13: =BM13*5% -> 393.125 | BO13: =BM13-BN13 -> 7469.375 | BQ13: 8 | BR13: 2 | BS13: 8 | BT13: 2 | BU13: 8 | BV13: 0 | BW13: 8 | BX13: 2 | BY13: 8 | BZ13: 2 | CA13: 8 | CB13: 2 | CC13: 8 | CE13: =SUM(BQ13,BS13,BU13,BW13,BY13,CA13,CC13) -> 56 | CF13: =SUM(BR13,BT13,BV13,BX13,BZ13,CB13,CD13) -> 10 | CG13: =IFERROR(INDEX(Settings!$F:$F, MATCH('PROJECT NAME NOV'!$B13 & "-" & 'PROJECT NAME NOV'!$C13, Settings!$H:$H,0)), "") -> 106.25 | CH13: =IFERROR(INDEX(Settings!$G:$G, MATCH('PROJECT NAME NOV'!$B13 & "-" & 'PROJECT NAME NOV'!$C13, Settings!$H:$H, 0)), "") -> 850 | CI13: =(CE13*CG13)+(CF13*CG13) -> 7012.5 | CJ13: =CI13*5% -> 350.625 | CK13: =CI13-CJ13 -> 6661.875 | CS13: =SUM(CM13,CO13,CQ13) -> 0 | CT13: =SUM(CN13,CP13,CR13) -> 0 | CU13: =IFERROR(INDEX(Settings!$F:$F, MATCH('PROJECT NAME NOV'!$B13 & "-" & 'PROJECT NAME NOV'!$C13, Settings!$H:$H,0)), "") -> 106.25 | CV13: =IFERROR(INDEX(Settings!$G:$G, MATCH('PROJECT NAME NOV'!$B13 & "-" & 'PROJECT NAME NOV'!$C13, Settings!$H:$H, 0)), "") -> 850 | CW13: =(CU13*CS13)+(CT13*CU13) -> 0 | CX13: =CW13*5% -> 0 | CY13: =CW13-CX13 -> 0 | DH13: ='Billable Till Date'!B9 & "-" & 'Billable Till Date'!C9 -> Task/Activity-Unit Type
B14: Ramakanth | C14: Carpenter Helper | D14: Labour-008 | E14: Rajesh | R14: =SUM(F14,H14,J14,L14,N14,P14) -> 0 | S14: =SUM(G14,I14,K14,M14,O14,Q14) -> 0 | T14: =IFERROR(INDEX(Settings!$F:$F, MATCH('PROJECT NAME NOV'!$B14 & "-" & 'PROJECT NAME NOV'!$C14, Settings!$H:$H,0)), "") -> 81.25 | U14: =IFERROR(INDEX(Settings!$G:$G, MATCH('PROJECT NAME NOV'!$B14 & "-" & 'PROJECT NAME NOV'!$C14, Settings!$H:$H, 0)), "") -> 650 | V14: =(R14*T14)+(S14*T14) -> 0 | W14: =V14*5% -> 0 | X14: =V14-W14 -> 0 | Y14: 8 | Z14: 0 | AA14: 8 | AB14: 2 | AC14: 0 | AD14: 0 | AE14: 8 | AF14: 2 | AG14: 8 | AH14: 2 | AI14: 8 | AJ14: 2 | AK14: 8 | AL14: 2 | AM14: =IFERROR(INDEX(Settings!$F:$F, MATCH('PROJECT NAME NOV'!$B14 & "-" & 'PROJECT NAME NOV'!$C14, Settings!$H:$H,0)), "") -> 81.25 | AN14: =IFERROR(INDEX(Settings!$G:$G, MATCH('PROJECT NAME NOV'!$B14 & "-" & 'PROJECT NAME NOV'!$C14, Settings!$H:$H, 0)), "") -> 650 | AO14: =SUM(Y14,AA14,AC14,AE14,AG14,AI14,AK14) -> 48 | AP14: =SUM(Z14,AB14,AD14,AF14,AH14,AJ14,AL14) -> 10 | AQ14: =(AO14*AM14)+(AP14*AM14) -> 4712.5 | AR14: =AQ14*5% -> 235.625 | AS14: =AQ14-AR14 -> 4476.875 | AU14: 8 | AV14: 2 | AW14: 8 | AX14: 4 | AY14: 8 | AZ14: 0 | BA14: 8 | BB14: 4 | BC14: 8 | BD14: 4 | BE14: 8 | BF14: 0 | BG14: 8 | BH14: 4 | BI14: =SUM(AU14,AW14,AY14,BA14,BC14,BE14,BG14) -> 56 | BJ14: =SUM(AV14,AX14,AZ14,BB14,BD14,BF14,BH14) -> 18 | BK14: =IFERROR(INDEX(Settings!$F:$F, MATCH('PROJECT NAME NOV'!$B14 & "-" & 'PROJECT NAME NOV'!$C14, Settings!$H:$H,0)), "") -> 81.25 | BL14: =IFERROR(INDEX(Settings!$G:$G, MATCH('PROJECT NAME NOV'!$B14 & "-" & 'PROJECT NAME NOV'!$C14, Settings!$H:$H, 0)), "") -> 650 | BM14: =(BI14*BK14)+(BJ14*BK14) -> 6012.5 | BN14: =BM14*5% -> 300.625 | BO14: =BM14-BN14 -> 5711.875 | BQ14: 8 | BR14: 2 | BS14: 8 | BT14: 2 | BU14: 8 | BV14: 0 | BW14: 8 | BX14: 2 | BY14: 8 | BZ14: 2 | CA14: 8 | CB14: 2 | CC14: 8 | CE14: =SUM(BQ14,BS14,BU14,BW14,BY14,CA14,CC14) -> 56 | CF14: =SUM(BR14,BT14,BV14,BX14,BZ14,CB14,CD14) -> 10 | CG14: =IFERROR(INDEX(Settings!$F:$F, MATCH('PROJECT NAME NOV'!$B14 & "-" & 'PROJECT NAME NOV'!$C14, Settings!$H:$H,0)), "") -> 81.25 | CH14: =IFERROR(INDEX(Settings!$G:$G, MATCH('PROJECT NAME NOV'!$B14 & "-" & 'PROJECT NAME NOV'!$C14, Settings!$H:$H, 0)), "") -> 650 | CI14: =(CE14*CG14)+(CF14*CG14) -> 5362.5 | CJ14: =CI14*5% -> 268.125 | CK14: =CI14-CJ14 -> 5094.375 | CM14: 8 | CN14: 4 | CO14: 8 | CP14: 4 | CS14: =SUM(CM14,CO14,CQ14) -> 16 | CT14: =SUM(CN14,CP14,CR14) -> 8 | CU14: =IFERROR(INDEX(Settings!$F:$F, MATCH('PROJECT NAME NOV'!$B14 & "-" & 'PROJECT NAME NOV'!$C14, Settings!$H:$H,0)), "") -> 81.25 | CV14: =IFERROR(INDEX(Settings!$G:$G, MATCH('PROJECT NAME NOV'!$B14 & "-" & 'PROJECT NAME NOV'!$C14, Settings!$H:$H, 0)), "") -> 650 | CW14: =(CU14*CS14)+(CT14*CU14) -> 1950 | CX14: =CW14*5% -> 97.5 | CY14: =CW14-CX14 -> 1852.5 | DH14: ='Billable Till Date'!B10 & "-" & 'Billable Till Date'!C10 -> Task/Activity-Unit Type
B15: Ramakanth | C15: Carpenter Helper | D15: Labour-009 | E15: Shivendra | F15: 8 | G15: 0 | H15: 8 | I15: 2 | J15: 8 | K15: 2 | L15: 8 | M15: 2 | N15: 8 | O15: 2 | R15: =SUM(F15,H15,J15,L15,N15,P15) -> 40 | S15: =SUM(G15,I15,K15,M15,O15,Q15) -> 8 | T15: =IFERROR(INDEX(Settings!$F:$F, MATCH('PROJECT NAME NOV'!$B15 & "-" & 'PROJECT NAME NOV'!$C15, Settings!$H:$H,0)), "") -> 81.25 | U15: =IFERROR(INDEX(Settings!$G:$G, MATCH('PROJECT NAME NOV'!$B15 & "-" & 'PROJECT NAME NOV'!$C15, Settings!$H:$H, 0)), "") -> 650 | V15: =(R15*T15)+(S15*T15) -> 3900 | W15: =V15*5% -> 195 | X15: =V15-W15 -> 3705 | Y15: 8 | Z15: 0 | AA15: 8 | AB15: 2 | AC15: 8 | AD15: 0 | AE15: 8 | AF15: 2 | AG15: 8 | AH15: 2 | AI15: 8 | AJ15: 2 | AK15: 8 | AL15: 2 | AM15: =IFERROR(INDEX(Settings!$F:$F, MATCH('PROJECT NAME NOV'!$B15 & "-" & 'PROJECT NAME NOV'!$C15, Settings!$H:$H,0)), "") -> 81.25 | AN15: =IFERROR(INDEX(Settings!$G:$G, MATCH('PROJECT NAME NOV'!$B15 & "-" & 'PROJECT NAME NOV'!$C15, Settings!$H:$H, 0)), "") -> 650 | AO15: =SUM(Y15,AA15,AC15,AE15,AG15,AI15,AK15) -> 56 | AP15: =SUM(Z15,AB15,AD15,AF15,AH15,AJ15,AL15) -> 10 | AQ15: =(AO15*AM15)+(AP15*AM15) -> 5362.5 | AR15: =AQ15*5% -> 268.125 | AS15: =AQ15-AR15 -> 5094.375 | AU15: 8 | AV15: 2 | AW15: 8 | AX15: 4 | AY15: 8 | AZ15: 0 | BA15: 8 | BB15: 4 | BC15: 8 | BD15: 4 | BE15: 8 | BF15: 0 | BG15: 0 | BH15: 4 | BI15: =SUM(AU15,AW15,AY15,BA15,BC15,BE15,BG15) -> 48 | BJ15: =SUM(AV15,AX15,AZ15,BB15,BD15,BF15,BH15) -> 18 | BK15: =IFERROR(INDEX(Settings!$F:$F, MATCH('PROJECT NAME NOV'!$B15 & "-" & 'PROJECT NAME NOV'!$C15, Settings!$H:$H,0)), "") -> 81.25 | BL15: =IFERROR(INDEX(Settings!$G:$G, MATCH('PROJECT NAME NOV'!$B15 & "-" & 'PROJECT NAME NOV'!$C15, Settings!$H:$H, 0)), "") -> 650 | BM15: =(BI15*BK15)+(BJ15*BK15) -> 5362.5 | BN15: =BM15*5% -> 268.125 | BO15: =BM15-BN15 -> 5094.375 | BQ15: 8 | BR15: 2 | BS15: 8 | BT15: 2 | BU15: 8 | BV15: 0 | BW15: 8 | BX15: 2 | BY15: 8 | BZ15: 2 | CA15: 8 | CB15: 2 | CC15: 8 | CE15: =SUM(BQ15,BS15,BU15,BW15,BY15,CA15,CC15) -> 56 | CF15: =SUM(BR15,BT15,BV15,BX15,BZ15,CB15,CD15) -> 10 | CG15: =IFERROR(INDEX(Settings!$F:$F, MATCH('PROJECT NAME NOV'!$B15 & "-" & 'PROJECT NAME NOV'!$C15, Settings!$H:$H,0)), "") -> 81.25 | CH15: =IFERROR(INDEX(Settings!$G:$G, MATCH('PROJECT NAME NOV'!$B15 & "-" & 'PROJECT NAME NOV'!$C15, Settings!$H:$H, 0)), "") -> 650 | CI15: =(CE15*CG15)+(CF15*CG15) -> 5362.5 | CJ15: =CI15*5% -> 268.125 | CK15: =CI15-CJ15 -> 5094.375 | CS15: =SUM(CM15,CO15,CQ15) -> 0 | CT15: =SUM(CN15,CP15,CR15) -> 0 | CU15: =IFERROR(INDEX(Settings!$F:$F, MATCH('PROJECT NAME NOV'!$B15 & "-" & 'PROJECT NAME NOV'!$C15, Settings!$H:$H,0)), "") -> 81.25 | CV15: =IFERROR(INDEX(Settings!$G:$G, MATCH('PROJECT NAME NOV'!$B15 & "-" & 'PROJECT NAME NOV'!$C15, Settings!$H:$H, 0)), "") -> 650 | CW15: =(CU15*CS15)+(CT15*CU15) -> 0 | CX15: =CW15*5% -> 0 | CY15: =CW15-CX15 -> 0 | DH15: ='Billable Till Date'!B11 & "-" & 'Billable Till Date'!C11 -> Task/Activity-Unit Type
B16: Ramakanth | C16: Carpenter Helper | D16: Labour-010 | E16: Ranjith | F16: 8 | G16: 0 | H16: 8 | I16: 2 | J16: 8 | K16: 2 | L16: 8 | M16: 2 | N16: 8 | O16: 2 | R16: =SUM(F16,H16,J16,L16,N16,P16) -> 40 | S16: =SUM(G16,I16,K16,M16,O16,Q16) -> 8 | T16: =IFERROR(INDEX(Settings!$F:$F, MATCH('PROJECT NAME NOV'!$B16 & "-" & 'PROJECT NAME NOV'!$C16, Settings!$H:$H,0)), "") -> 81.25 | U16: =IFERROR(INDEX(Settings!$G:$G, MATCH('PROJECT NAME NOV'!$B16 & "-" & 'PROJECT NAME NOV'!$C16, Settings!$H:$H, 0)), "") -> 650 | V16: =(R16*T16)+(S16*T16) -> 3900 | W16: =V16*5% -> 195 | X16: =V16-W16 -> 3705 | Y16: 8 | Z16: 0 | AA16: 8 | AB16: 2 | AC16: 8 | AD16: 0 | AE16: 8 | AF16: 2 | AG16: 8 | AH16: 2 | AI16: 8 | AJ16: 2 | AK16: 8 | AL16: 2 | AM16: =IFERROR(INDEX(Settings!$F:$F, MATCH('PROJECT NAME NOV'!$B16 & "-" & 'PROJECT NAME NOV'!$C16, Settings!$H:$H,0)), "") -> 81.25 | AN16: =IFERROR(INDEX(Settings!$G:$G, MATCH('PROJECT NAME NOV'!$B16 & "-" & 'PROJECT NAME NOV'!$C16, Settings!$H:$H, 0)), "") -> 650 | AO16: =SUM(Y16,AA16,AC16,AE16,AG16,AI16,AK16) -> 56 | AP16: =SUM(Z16,AB16,AD16,AF16,AH16,AJ16,AL16) -> 10 | AQ16: =(AO16*AM16)+(AP16*AM16) -> 5362.5 | AR16: =AQ16*5% -> 268.125 | AS16: =AQ16-AR16 -> 5094.375 | AU16: 8 | AV16: 2 | AW16: 8 | AX16: 4 | AY16: 8 | AZ16: 0 | BA16: 8 | BB16: 4 | BC16: 8 | BD16: 4 | BE16: 8 | BF16: 0 | BG16: 0 | BH16: 4 | BI16: =SUM(AU16,AW16,AY16,BA16,BC16,BE16,BG16) -> 48 | BJ16: =SUM(AV16,AX16,AZ16,BB16,BD16,BF16,BH16) -> 18 | BK16: =IFERROR(INDEX(Settings!$F:$F, MATCH('PROJECT NAME NOV'!$B16 & "-" & 'PROJECT NAME NOV'!$C16, Settings!$H:$H,0)), "") -> 81.25 | BL16: =IFERROR(INDEX(Settings!$G:$G, MATCH('PROJECT NAME NOV'!$B16 & "-" & 'PROJECT NAME NOV'!$C16, Settings!$H:$H, 0)), "") -> 650 | BM16: =(BI16*BK16)+(BJ16*BK16) -> 5362.5 | BN16: =BM16*5% -> 268.125 | BO16: =BM16-BN16 -> 5094.375 | BQ16: 8 | BR16: 2 | BS16: 8 | BT16: 2 | BU16: 8 | BV16: 0 | BW16: 8 | BX16: 2 | BY16: 8 | BZ16: 2 | CA16: 8 | CB16: 2 | CC16: 8 | CE16: =SUM(BQ16,BS16,BU16,BW16,BY16,CA16,CC16) -> 56 | CF16: =SUM(BR16,BT16,BV16,BX16,BZ16,CB16,CD16) -> 10 | CG16: =IFERROR(INDEX(Settings!$F:$F, MATCH('PROJECT NAME NOV'!$B16 & "-" & 'PROJECT NAME NOV'!$C16, Settings!$H:$H,0)), "") -> 81.25 | CH16: =IFERROR(INDEX(Settings!$G:$G, MATCH('PROJECT NAME NOV'!$B16 & "-" & 'PROJECT NAME NOV'!$C16, Settings!$H:$H, 0)), "") -> 650 | CI16: =(CE16*CG16)+(CF16*CG16) -> 5362.5 | CJ16: =CI16*5% -> 268.125 | CK16: =CI16-CJ16 -> 5094.375 | CS16: =SUM(CM16,CO16,CQ16) -> 0 | CT16: =SUM(CN16,CP16,CR16) -> 0 | CU16: =IFERROR(INDEX(Settings!$F:$F, MATCH('PROJECT NAME NOV'!$B16 & "-" & 'PROJECT NAME NOV'!$C16, Settings!$H:$H,0)), "") -> 81.25 | CV16: =IFERROR(INDEX(Settings!$G:$G, MATCH('PROJECT NAME NOV'!$B16 & "-" & 'PROJECT NAME NOV'!$C16, Settings!$H:$H, 0)), "") -> 650 | CW16: =(CU16*CS16)+(CT16*CU16) -> 0 | CX16: =CW16*5% -> 0 | CY16: =CW16-CX16 -> 0 | DH16: ='Billable Till Date'!B12 & "-" & 'Billable Till Date'!C12 -> Task/Activity-Unit Type
B17: Ramakanth | C17: Carpenter | D17: Labour-011 | E17: Sharada Prasad | F17: 8 | G17: 0 | H17: 8 | I17: 2 | J17: 8 | K17: 2 | L17: 8 | M17: 2 | N17: 8 | O17: 2 | R17: =SUM(F17,H17,J17,L17,N17,P17) -> 40 | S17: =SUM(G17,I17,K17,M17,O17,Q17) -> 8 | T17: =IFERROR(INDEX(Settings!$F:$F, MATCH('PROJECT NAME NOV'!$B17 & "-" & 'PROJECT NAME NOV'!$C17, Settings!$H:$H,0)), "") -> 106.25 | U17: =IFERROR(INDEX(Settings!$G:$G, MATCH('PROJECT NAME NOV'!$B17 & "-" & 'PROJECT NAME NOV'!$C17, Settings!$H:$H, 0)), "") -> 850 | V17: =(R17*T17)+(S17*T17) -> 5100 | W17: =V17*5% -> 255 | X17: =V17-W17 -> 4845 | Y17: 8 | Z17: 0 | AA17: 8 | AB17: 2 | AC17: 8 | AD17: 0 | AE17: 8 | AF17: 2 | AG17: 8 | AH17: 2 | AI17: 8 | AJ17: 2 | AK17: 8 | AL17: 2 | AM17: =IFERROR(INDEX(Settings!$F:$F, MATCH('PROJECT NAME NOV'!$B17 & "-" & 'PROJECT NAME NOV'!$C17, Settings!$H:$H,0)), "") -> 106.25 | AN17: =IFERROR(INDEX(Settings!$G:$G, MATCH('PROJECT NAME NOV'!$B17 & "-" & 'PROJECT NAME NOV'!$C17, Settings!$H:$H, 0)), "") -> 850 | AO17: =SUM(Y17,AA17,AC17,AE17,AG17,AI17,AK17) -> 56 | AP17: =SUM(Z17,AB17,AD17,AF17,AH17,AJ17,AL17) -> 10 | AQ17: =(AO17*AM17)+(AP17*AM17) -> 7012.5 | AR17: =AQ17*5% -> 350.625 | AS17: =AQ17-AR17 -> 6661.875 | AU17: 8 | AV17: 0 | AW17: 8 | AX17: 4 | AY17: 8 | AZ17: 0 | BA17: 8 | BB17: 4 | BC17: 8 | BD17: 4 | BE17: 8 | BF17: 0 | BG17: 8 | BH17: 4 | BI17: =SUM(AU17,AW17,AY17,BA17,BC17,BE17,BG17) -> 56 | BJ17: =SUM(AV17,AX17,AZ17,BB17,BD17,BF17,BH17) -> 16 | BK17: =IFERROR(INDEX(Settings!$F:$F, MATCH('PROJECT NAME NOV'!$B17 & "-" & 'PROJECT NAME NOV'!$C17, Settings!$H:$H,0)), "") -> 106.25 | BL17: =IFERROR(INDEX(Settings!$G:$G, MATCH('PROJECT NAME NOV'!$B17 & "-" & 'PROJECT NAME NOV'!$C17, Settings!$H:$H, 0)), "") -> 850 | BM17: =(BI17*BK17)+(BJ17*BK17) -> 7650 | BN17: =BM17*5% -> 382.5 | BO17: =BM17-BN17 -> 7267.5 | BQ17: 8 | BR17: 2 | BS17: 8 | BT17: 2 | BU17: 8 | BV17: 0 | BW17: 8 | BX17: 2 | BY17: 8 | BZ17: 2 | CA17: 8 | CB17: 2 | CC17: 8 | CE17: =SUM(BQ17,BS17,BU17,BW17,BY17,CA17,CC17) -> 56 | CF17: =SUM(BR17,BT17,BV17,BX17,BZ17,CB17,CD17) -> 10 | CG17: =IFERROR(INDEX(Settings!$F:$F, MATCH('PROJECT NAME NOV'!$B17 & "-" & 'PROJECT NAME NOV'!$C17, Settings!$H:$H,0)), "") -> 106.25 | CH17: =IFERROR(INDEX(Settings!$G:$G, MATCH('PROJECT NAME NOV'!$B17 & "-" & 'PROJECT NAME NOV'!$C17, Settings!$H:$H, 0)), "") -> 850 | CI17: =(CE17*CG17)+(CF17*CG17) -> 7012.5 | CJ17: =CI17*5% -> 350.625 | CK17: =CI17-CJ17 -> 6661.875 | CM17: 8 | CN17: 4 | CO17: 8 | CP17: 4 | CS17: =SUM(CM17,CO17,CQ17) -> 16 | CT17: =SUM(CN17,CP17,CR17) -> 8 | CU17: =IFERROR(INDEX(Settings!$F:$F, MATCH('PROJECT NAME NOV'!$B17 & "-" & 'PROJECT NAME NOV'!$C17, Settings!$H:$H,0)), "") -> 106.25 | CV17: =IFERROR(INDEX(Settings!$G:$G, MATCH('PROJECT NAME NOV'!$B17 & "-" & 'PROJECT NAME NOV'!$C17, Settings!$H:$H, 0)), "") -> 850 | CW17: =(CU17*CS17)+(CT17*CU17) -> 2550 | CX17: =CW17*5% -> 127.5 | CY17: =CW17-CX17 -> 2422.5 | DH17: ='Billable Till Date'!B13 & "-" & 'Billable Till Date'!C13 -> Task/Activity-Unit Type
B18: Ramakanth | C18: Carpenter | D18: Labour-012 | E18: Kashi Prasad | F18: 8 | G18: 0 | H18: 8 | I18: 2 | J18: 8 | K18: 2 | L18: 8 | M18: 2 | N18: 8 | O18: 2 | R18: =SUM(F18,H18,J18,L18,N18,P18) -> 40 | S18: =SUM(G18,I18,K18,M18,O18,Q18) -> 8 | T18: =IFERROR(INDEX(Settings!$F:$F, MATCH('PROJECT NAME NOV'!$B18 & "-" & 'PROJECT NAME NOV'!$C18, Settings!$H:$H,0)), "") -> 106.25 | U18: =IFERROR(INDEX(Settings!$G:$G, MATCH('PROJECT NAME NOV'!$B18 & "-" & 'PROJECT NAME NOV'!$C18, Settings!$H:$H, 0)), "") -> 850 | V18: =(R18*T18)+(S18*T18) -> 5100 | W18: =V18*5% -> 255 | X18: =V18-W18 -> 4845 | Y18: 8 | Z18: 0 | AA18: 8 | AB18: 2 | AC18: 8 | AD18: 0 | AE18: 8 | AF18: 2 | AG18: 8 | AH18: 2 | AI18: 8 | AJ18: 2 | AK18: 8 | AL18: 2 | AM18: =IFERROR(INDEX(Settings!$F:$F, MATCH('PROJECT NAME NOV'!$B18 & "-" & 'PROJECT NAME NOV'!$C18, Settings!$H:$H,0)), "") -> 106.25 | AN18: =IFERROR(INDEX(Settings!$G:$G, MATCH('PROJECT NAME NOV'!$B18 & "-" & 'PROJECT NAME NOV'!$C18, Settings!$H:$H, 0)), "") -> 850 | AO18: =SUM(Y18,AA18,AC18,AE18,AG18,AI18,AK18) -> 56 | AP18: =SUM(Z18,AB18,AD18,AF18,AH18,AJ18,AL18) -> 10 | AQ18: =(AO18*AM18)+(AP18*AM18) -> 7012.5 | AR18: =AQ18*5% -> 350.625 | AS18: =AQ18-AR18 -> 6661.875 | AU18: 8 | AV18: 0 | AW18: 8 | AX18: 4 | AY18: 8 | AZ18: 0 | BA18: 8 | BB18: 4 | BC18: 8 | BD18: 4 | BE18: 8 | BF18: 0 | BG18: 8 | BH18: 4 | BI18: =SUM(AU18,AW18,AY18,BA18,BC18,BE18,BG18) -> 56 | BJ18: =SUM(AV18,AX18,AZ18,BB18,BD18,BF18,BH18) -> 16 | BK18: =IFERROR(INDEX(Settings!$F:$F, MATCH('PROJECT NAME NOV'!$B18 & "-" & 'PROJECT NAME NOV'!$C18, Settings!$H:$H,0)), "") -> 106.25 | BL18: =IFERROR(INDEX(Settings!$G:$G, MATCH('PROJECT NAME NOV'!$B18 & "-" & 'PROJECT NAME NOV'!$C18, Settings!$H:$H, 0)), "") -> 850 | BM18: =(BI18*BK18)+(BJ18*BK18) -> 7650 | BN18: =BM18*5% -> 382.5 | BO18: =BM18-BN18 -> 7267.5 | BQ18: 0 | BR18: 0 | BS18: 0 | BT18: 0 | BU18: 0 | BV18: 0 | BW18: 0 | BX18: 0 | BY18: 0 | BZ18: 0 | CA18: 0 | CB18: 0 | CC18: 0 | CE18: =SUM(BQ18,BS18,BU18,BW18,BY18,CA18,CC18) -> 0 | CF18: =SUM(BR18,BT18,BV18,BX18,BZ18,CB18,CD18) -> 0 | CG18: =IFERROR(INDEX(Settings!$F:$F, MATCH('PROJECT NAME NOV'!$B18 & "-" & 'PROJECT NAME NOV'!$C18, Settings!$H:$H,0)), "") -> 106.25 | CH18: =IFERROR(INDEX(Settings!$G:$G, MATCH('PROJECT NAME NOV'!$B18 & "-" & 'PROJECT NAME NOV'!$C18, Settings!$H:$H, 0)), "") -> 850 | CI18: =(CE18*CG18)+(CF18*CG18) -> 0 | CJ18: =CI18*5% -> 0 | CK18: =CI18-CJ18 -> 0 | CM18: 8 | CN18: 4 | CO18: 8 | CP18: 4 | CS18: =SUM(CM18,CO18,CQ18) -> 16 | CT18: =SUM(CN18,CP18,CR18) -> 8 | CU18: =IFERROR(INDEX(Settings!$F:$F, MATCH('PROJECT NAME NOV'!$B18 & "-" & 'PROJECT NAME NOV'!$C18, Settings!$H:$H,0)), "") -> 106.25 | CV18: =IFERROR(INDEX(Settings!$G:$G, MATCH('PROJECT NAME NOV'!$B18 & "-" & 'PROJECT NAME NOV'!$C18, Settings!$H:$H, 0)), "") -> 850 | CW18: =(CU18*CS18)+(CT18*CU18) -> 2550 | CX18: =CW18*5% -> 127.5 | CY18: =CW18-CX18 -> 2422.5 | DH18: ='Billable Till Date'!B14 & "-" & 'Billable Till Date'!C14 -> Task/Activity-Unit Type
B19: Ramakanth | C19: Barbender Helper | D19: Labour-013 | E19: Abilash | F19: 0 | G19: 0 | H19: 8 | I19: 2 | J19: 8 | K19: 2 | L19: 8 | M19: 2 | N19: 8 | O19: 2 | R19: =SUM(F19,H19,J19,L19,N19,P19) -> 32 | S19: =SUM(G19,I19,K19,M19,O19,Q19) -> 8 | T19: =IFERROR(INDEX(Settings!$F:$F, MATCH('PROJECT NAME NOV'!$B19 & "-" & 'PROJECT NAME NOV'!$C19, Settings!$H:$H,0)), "") -> 81.25 | U19: =IFERROR(INDEX(Settings!$G:$G, MATCH('PROJECT NAME NOV'!$B19 & "-" & 'PROJECT NAME NOV'!$C19, Settings!$H:$H, 0)), "") -> 650 | V19: =(R19*T19)+(S19*T19) -> 3250 | W19: =V19*5% -> 162.5 | X19: =V19-W19 -> 3087.5 | Y19: 8 | Z19: 0 | AA19: 8 | AB19: 2 | AC19: 0 | AD19: 0 | AE19: 8 | AF19: 2 | AG19: 8 | AH19: 2 | AI19: 8 | AJ19: 2 | AK19: 8 | AL19: 2 | AM19: =IFERROR(INDEX(Settings!$F:$F, MATCH('PROJECT NAME NOV'!$B19 & "-" & 'PROJECT NAME NOV'!$C19, Settings!$H:$H,0)), "") -> 81.25 | AN19: =IFERROR(INDEX(Settings!$G:$G, MATCH('PROJECT NAME NOV'!$B19 & "-" & 'PROJECT NAME NOV'!$C19, Settings!$H:$H, 0)), "") -> 650 | AO19: =SUM(Y19,AA19,AC19,AE19,AG19,AI19,AK19) -> 48 | AP19: =SUM(Z19,AB19,AD19,AF19,AH19,AJ19,AL19) -> 10 | AQ19: =(AO19*AM19)+(AP19*AM19) -> 4712.5 | AR19: =AQ19*5% -> 235.625 | AS19: =AQ19-AR19 -> 4476.875 | AU19: 8 | AV19: 0 | AW19: 8 | AX19: 4 | AY19: 8 | AZ19: 0 | BA19: 8 | BB19: 4 | BC19: 8 | BD19: 4 | BE19: 8 | BF19: 0 | BG19: 8 | BH19: 4 | BI19: =SUM(AU19,AW19,AY19,BA19,BC19,BE19,BG19) -> 56 | BJ19: =SUM(AV19,AX19,AZ19,BB19,BD19,BF19,BH19) -> 16 | BK19: =IFERROR(INDEX(Settings!$F:$F, MATCH('PROJECT NAME NOV'!$B19 & "-" & 'PROJECT NAME NOV'!$C19, Settings!$H:$H,0)), "") -> 81.25 | BL19: =IFERROR(INDEX(Settings!$G:$G, MATCH('PROJECT NAME NOV'!$B19 & "-" & 'PROJECT NAME NOV'!$C19, Settings!$H:$H, 0)), "") -> 650 | BM19: =(BI19*BK19)+(BJ19*BK19) -> 5850 | BN19: =BM19*5% -> 292.5 | BO19: =BM19-BN19 -> 5557.5 | BQ19: 0 | BR19: 0 | BS19: 0 | BT19: 0 | BU19: 0 | BV19: 0 | BW19: 0 | BX19: 0 | BY19: 0 | BZ19: 0 | CA19: 0 | CB19: 0 | CC19: 0 | CE19: =SUM(BQ19,BS19,BU19,BW19,BY19,CA19,CC19) -> 0 | CF19: =SUM(BR19,BT19,BV19,BX19,BZ19,CB19,CD19) -> 0 | CG19: =IFERROR(INDEX(Settings!$F:$F, MATCH('PROJECT NAME NOV'!$B19 & "-" & 'PROJECT NAME NOV'!$C19, Settings!$H:$H,0)), "") -> 81.25 | CH19: =IFERROR(INDEX(Settings!$G:$G, MATCH('PROJECT NAME NOV'!$B19 & "-" & 'PROJECT NAME NOV'!$C19, Settings!$H:$H, 0)), "") -> 650 | CI19: =(CE19*CG19)+(CF19*CG19) -> 0 | CJ19: =CI19*5% -> 0 | CK19: =CI19-CJ19 -> 0 | CS19: =SUM(CM19,CO19,CQ19) -> 0 | CT19: =SUM(CN19,CP19,CR19) -> 0 | CU19: =IFERROR(INDEX(Settings!$F:$F, MATCH('PROJECT NAME NOV'!$B19 & "-" & 'PROJECT NAME NOV'!$C19, Settings!$H:$H,0)), "") -> 81.25 | CV19: =IFERROR(INDEX(Settings!$G:$G, MATCH('PROJECT NAME NOV'!$B19 & "-" & 'PROJECT NAME NOV'!$C19, Settings!$H:$H, 0)), "") -> 650 | CW19: =(CU19*CS19)+(CT19*CU19) -> 0 | CX19: =CW19*5% -> 0 | CY19: =CW19-CX19 -> 0 | DH19: ='Billable Till Date'!B15 & "-" & 'Billable Till Date'!C15 -> Task/Activity-Unit Type
B20: Ramakanth | C20: Barbender Fitter | D20: Labour-014 | E20: Ramesh | F20: 8 | G20: 0 | H20: 8 | I20: 2 | J20: 8 | K20: 2 | L20: 0 | M20: 0 | N20: 8 | O20: 2 | R20: =SUM(F20,H20,J20,L20,N20,P20) -> 32 | S20: =SUM(G20,I20,K20,M20,O20,Q20) -> 6 | T20: =IFERROR(INDEX(Settings!$F:$F, MATCH('PROJECT NAME NOV'!$B20 & "-" & 'PROJECT NAME NOV'!$C20, Settings!$H:$H,0)), "") -> 106.25 | U20: =IFERROR(INDEX(Settings!$G:$G, MATCH('PROJECT NAME NOV'!$B20 & "-" & 'PROJECT NAME NOV'!$C20, Settings!$H:$H, 0)), "") -> 850 | V20: =(R20*T20)+(S20*T20) -> 4037.5 | W20: =V20*5% -> 201.875 | X20: =V20-W20 -> 3835.625 | Y20: 8 | Z20: 0 | AA20: 8 | AB20: 2 | AC20: 8 | AD20: 0 | AE20: 8 | AF20: 2 | AG20: 8 | AH20: 2 | AI20: 0 | AJ20: 0 | AK20: 8 | AL20: 2 | AM20: =IFERROR(INDEX(Settings!$F:$F, MATCH('PROJECT NAME NOV'!$B20 & "-" & 'PROJECT NAME NOV'!$C20, Settings!$H:$H,0)), "") -> 106.25 | AN20: =IFERROR(INDEX(Settings!$G:$G, MATCH('PROJECT NAME NOV'!$B20 & "-" & 'PROJECT NAME NOV'!$C20, Settings!$H:$H, 0)), "") -> 850 | AO20: =SUM(Y20,AA20,AC20,AE20,AG20,AI20,AK20) -> 48 | AP20: =SUM(Z20,AB20,AD20,AF20,AH20,AJ20,AL20) -> 8 | AQ20: =(AO20*AM20)+(AP20*AM20) -> 5950 | AR20: =AQ20*5% -> 297.5 | AS20: =AQ20-AR20 -> 5652.5 | AU20: 8 | AV20: 0 | AW20: 0 | AX20: 0 | AY20: 8 | AZ20: 0 | BA20: 8 | BB20: 4 | BC20: 8 | BD20: 4 | BE20: 8 | BF20: 0 | BG20: 8 | BH20: 4 | BI20: =SUM(AU20,AW20,AY20,BA20,BC20,BE20,BG20) -> 48 | BJ20: =SUM(AV20,AX20,AZ20,BB20,BD20,BF20,BH20) -> 12 | BK20: =IFERROR(INDEX(Settings!$F:$F, MATCH('PROJECT NAME NOV'!$B20 & "-" & 'PROJECT NAME NOV'!$C20, Settings!$H:$H,0)), "") -> 106.25 | BL20: =IFERROR(INDEX(Settings!$G:$G, MATCH('PROJECT NAME NOV'!$B20 & "-" & 'PROJECT NAME NOV'!$C20, Settings!$H:$H, 0)), "") -> 850 | BM20: =(BI20*BK20)+(BJ20*BK20) -> 6375 | BN20: =BM20*5% -> 318.75 | BO20: =BM20-BN20 -> 6056.25 | BQ20: 0 | BR20: 0 | BS20: 0 | BT20: 0 | BU20: 0 | BV20: 0 | BW20: 0 | BX20: 0 | BY20: 0 | BZ20: 0 | CA20: 0 | CB20: 0 | CC20: 0 | CE20: =SUM(BQ20,BS20,BU20,BW20,BY20,CA20,CC20) -> 0 | CF20: =SUM(BR20,BT20,BV20,BX20,BZ20,CB20,CD20) -> 0 | CG20: =IFERROR(INDEX(Settings!$F:$F, MATCH('PROJECT NAME NOV'!$B20 & "-" & 'PROJECT NAME NOV'!$C20, Settings!$H:$H,0)), "") -> 106.25 | CH20: =IFERROR(INDEX(Settings!$G:$G, MATCH('PROJECT NAME NOV'!$B20 & "-" & 'PROJECT NAME NOV'!$C20, Settings!$H:$H, 0)), "") -> 850 | CI20: =(CE20*CG20)+(CF20*CG20) -> 0 | CJ20: =CI20*5% -> 0 | CK20: =CI20-CJ20 -> 0 | CM20: 8 | CN20: 4 | CO20: 8 | CP20: 4 | CS20: =SUM(CM20,CO20,CQ20) -> 16 | CT20: =SUM(CN20,CP20,CR20) -> 8 | CU20: =IFERROR(INDEX(Settings!$F:$F, MATCH('PROJECT NAME NOV'!$B20 & "-" & 'PROJECT NAME NOV'!$C20, Settings!$H:$H,0)), "") -> 106.25 | CV20: =IFERROR(INDEX(Settings!$G:$G, MATCH('PROJECT NAME NOV'!$B20 & "-" & 'PROJECT NAME NOV'!$C20, Settings!$H:$H, 0)), "") -> 850 | CW20: =(CU20*CS20)+(CT20*CU20) -> 2550 | CX20: =CW20*5% -> 127.5 | CY20: =CW20-CX20 -> 2422.5 | DH20: ='Billable Till Date'!B16 & "-" & 'Billable Till Date'!C16 -> Task/Activity-Unit Type
B21: Ramakanth | C21: Barbender Helper | D21: Labour-015 | E21: Tanu Kori | F21: 8 | G21: 0 | H21: 0 | I21: 0 | J21: 0 | K21: 0 | L21: 0 | M21: 0 | N21: 8 | O21: 2 | R21: =SUM(F21,H21,J21,L21,N21,P21) -> 16 | S21: =SUM(G21,I21,K21,M21,O21,Q21) -> 2 | T21: =IFERROR(INDEX(Settings!$F:$F, MATCH('PROJECT NAME NOV'!$B21 & "-" & 'PROJECT NAME NOV'!$C21, Settings!$H:$H,0)), "") -> 81.25 | U21: =IFERROR(INDEX(Settings!$G:$G, MATCH('PROJECT NAME NOV'!$B21 & "-" & 'PROJECT NAME NOV'!$C21, Settings!$H:$H, 0)), "") -> 650 | V21: =(R21*T21)+(S21*T21) -> 1462.5 | W21: =V21*5% -> 73.125 | X21: =V21-W21 -> 1389.375 | Y21: 8 | Z21: 0 | AA21: 8 | AB21: 2 | AC21: 8 | AD21: 0 | AE21: 0 | AF21: 0 | AG21: 0 | AH21: 0 | AI21: 0 | AJ21: 0 | AK21: 8 | AL21: 2 | AM21: =IFERROR(INDEX(Settings!$F:$F, MATCH('PROJECT NAME NOV'!$B21 & "-" & 'PROJECT NAME NOV'!$C21, Settings!$H:$H,0)), "") -> 81.25 | AN21: =IFERROR(INDEX(Settings!$G:$G, MATCH('PROJECT NAME NOV'!$B21 & "-" & 'PROJECT NAME NOV'!$C21, Settings!$H:$H, 0)), "") -> 650 | AO21: =SUM(Y21,AA21,AC21,AE21,AG21,AI21,AK21) -> 32 | AP21: =SUM(Z21,AB21,AD21,AF21,AH21,AJ21,AL21) -> 4 | AQ21: =(AO21*AM21)+(AP21*AM21) -> 2925 | AR21: =AQ21*5% -> 146.25 | AS21: =AQ21-AR21 -> 2778.75 | AU21: 8 | AV21: 0 | AW21: 8 | AX21: 4 | AY21: 8 | AZ21: 0 | BA21: 8 | BB21: 4 | BC21: 8 | BD21: 4 | BE21: 8 | BF21: 0 | BG21: 8 | BH21: 4 | BI21: =SUM(AU21,AW21,AY21,BA21,BC21,BE21,BG21) -> 56 | BJ21: =SUM(AV21,AX21,AZ21,BB21,BD21,BF21,BH21) -> 16 | BK21: =IFERROR(INDEX(Settings!$F:$F, MATCH('PROJECT NAME NOV'!$B21 & "-" & 'PROJECT NAME NOV'!$C21, Settings!$H:$H,0)), "") -> 81.25 | BL21: =IFERROR(INDEX(Settings!$G:$G, MATCH('PROJECT NAME NOV'!$B21 & "-" & 'PROJECT NAME NOV'!$C21, Settings!$H:$H, 0)), "") -> 650 | BM21: =(BI21*BK21)+(BJ21*BK21) -> 5850 | BN21: =BM21*5% -> 292.5 | BO21: =BM21-BN21 -> 5557.5 | BQ21: 0 | BR21: 0 | BS21: 0 | BT21: 0 | BU21: 0 | BV21: 0 | BW21: 0 | BX21: 0 | BY21: 0 | BZ21: 0 | CA21: 0 | CB21: 0 | CC21: 0 | CE21: =SUM(BQ21,BS21,BU21,BW21,BY21,CA21,CC21) -> 0 | CF21: =SUM(BR21,BT21,BV21,BX21,BZ21,CB21,CD21) -> 0 | CG21: =IFERROR(INDEX(Settings!$F:$F, MATCH('PROJECT NAME NOV'!$B21 & "-" & 'PROJECT NAME NOV'!$C21, Settings!$H:$H,0)), "") -> 81.25 | CH21: =IFERROR(INDEX(Settings!$G:$G, MATCH('PROJECT NAME NOV'!$B21 & "-" & 'PROJECT NAME NOV'!$C21, Settings!$H:$H, 0)), "") -> 650 | CI21: =(CE21*CG21)+(CF21*CG21) -> 0 | CJ21: =CI21*5% -> 0 | CK21: =CI21-CJ21 -> 0 | CM21: 8 | CN21: 4 | CO21: 8 | CP21: 4 | CS21: =SUM(CM21,CO21,CQ21) -> 16 | CT21: =SUM(CN21,CP21,CR21) -> 8 | CU21: =IFERROR(INDEX(Settings!$F:$F, MATCH('PROJECT NAME NOV'!$B21 & "-" & 'PROJECT NAME NOV'!$C21, Settings!$H:$H,0)), "") -> 81.25 | CV21: =IFERROR(INDEX(Settings!$G:$G, MATCH('PROJECT NAME NOV'!$B21 & "-" & 'PROJECT NAME NOV'!$C21, Settings!$H:$H, 0)), "") -> 650 | CW21: =(CU21*CS21)+(CT21*CU21) -> 1950 | CX21: =CW21*5% -> 97.5 | CY21: =CW21-CX21 -> 1852.5 | DH21: ='Billable Till Date'!B17 & "-" & 'Billable Till Date'!C17 -> Task/Activity-Unit Type
B22: Ramakanth | C22: Barbender Helper | D22: Labour-016 | E22: Vinit Adivasi | F22: 8 | G22: 0 | H22: 8 | I22: 2 | J22: 8 | K22: 2 | L22: 0 | M22: 0 | N22: 8 | O22: 2 | R22: =SUM(F22,H22,J22,L22,N22,P22) -> 32 | S22: =SUM(G22,I22,K22,M22,O22,Q22) -> 6 | T22: =IFERROR(INDEX(Settings!$F:$F, MATCH('PROJECT NAME NOV'!$B22 & "-" & 'PROJECT NAME NOV'!$C22, Settings!$H:$H,0)), "") -> 81.25 | U22: =IFERROR(INDEX(Settings!$G:$G, MATCH('PROJECT NAME NOV'!$B22 & "-" & 'PROJECT NAME NOV'!$C22, Settings!$H:$H, 0)), "") -> 650 | V22: =(R22*T22)+(S22*T22) -> 3087.5 | W22: =V22*5% -> 154.375 | X22: =V22-W22 -> 2933.125 | Y22: 8 | Z22: 0 | AA22: 8 | AB22: 2 | AC22: 8 | AD22: 0 | AE22: 8 | AF22: 2 | AG22: 8 | AH22: 2 | AI22: 0 | AJ22: 0 | AK22: 8 | AL22: 2 | AM22: =IFERROR(INDEX(Settings!$F:$F, MATCH('PROJECT NAME NOV'!$B22 & "-" & 'PROJECT NAME NOV'!$C22, Settings!$H:$H,0)), "") -> 81.25 | AN22: =IFERROR(INDEX(Settings!$G:$G, MATCH('PROJECT NAME NOV'!$B22 & "-" & 'PROJECT NAME NOV'!$C22, Settings!$H:$H, 0)), "") -> 650 | AO22: =SUM(Y22,AA22,AC22,AE22,AG22,AI22,AK22) -> 48 | AP22: =SUM(Z22,AB22,AD22,AF22,AH22,AJ22,AL22) -> 8 | AQ22: =(AO22*AM22)+(AP22*AM22) -> 4550 | AR22: =AQ22*5% -> 227.5 | AS22: =AQ22-AR22 -> 4322.5 | AU22: 8 | AV22: 0 | AW22: 8 | AX22: 4 | AY22: 8 | AZ22: 0 | BA22: 8 | BB22: 4 | BC22: 8 | BD22: 4 | BE22: 8 | BF22: 0 | BG22: 8 | BH22: 4 | BI22: =SUM(AU22,AW22,AY22,BA22,BC22,BE22,BG22) -> 56 | BJ22: =SUM(AV22,AX22,AZ22,BB22,BD22,BF22,BH22) -> 16 | BK22: =IFERROR(INDEX(Settings!$F:$F, MATCH('PROJECT NAME NOV'!$B22 & "-" & 'PROJECT NAME NOV'!$C22, Settings!$H:$H,0)), "") -> 81.25 | BL22: =IFERROR(INDEX(Settings!$G:$G, MATCH('PROJECT NAME NOV'!$B22 & "-" & 'PROJECT NAME NOV'!$C22, Settings!$H:$H, 0)), "") -> 650 | BM22: =(BI22*BK22)+(BJ22*BK22) -> 5850 | BN22: =BM22*5% -> 292.5 | BO22: =BM22-BN22 -> 5557.5 | BQ22: 8 | BR22: 2 | BS22: 8 | BT22: 2 | BU22: 8 | BV22: 0 | BW22: 8 | BX22: 2 | BY22: 8 | BZ22: 2 | CA22: 8 | CB22: 2 | CC22: 8 | CE22: =SUM(BQ22,BS22,BU22,BW22,BY22,CA22,CC22) -> 56 | CF22: =SUM(BR22,BT22,BV22,BX22,BZ22,CB22,CD22) -> 10 | CG22: =IFERROR(INDEX(Settings!$F:$F, MATCH('PROJECT NAME NOV'!$B22 & "-" & 'PROJECT NAME NOV'!$C22, Settings!$H:$H,0)), "") -> 81.25 | CH22: =IFERROR(INDEX(Settings!$G:$G, MATCH('PROJECT NAME NOV'!$B22 & "-" & 'PROJECT NAME NOV'!$C22, Settings!$H:$H, 0)), "") -> 650 | CI22: =(CE22*CG22)+(CF22*CG22) -> 5362.5 | CJ22: =CI22*5% -> 268.125 | CK22: =CI22-CJ22 -> 5094.375 | CM22: 8 | CN22: 4 | CO22: 8 | CP22: 4 | CS22: =SUM(CM22,CO22,CQ22) -> 16 | CT22: =SUM(CN22,CP22,CR22) -> 8 | CU22: =IFERROR(INDEX(Settings!$F:$F, MATCH('PROJECT NAME NOV'!$B22 & "-" & 'PROJECT NAME NOV'!$C22, Settings!$H:$H,0)), "") -> 81.25 | CV22: =IFERROR(INDEX(Settings!$G:$G, MATCH('PROJECT NAME NOV'!$B22 & "-" & 'PROJECT NAME NOV'!$C22, Settings!$H:$H, 0)), "") -> 650 | CW22: =(CU22*CS22)+(CT22*CU22) -> 1950 | CX22: =CW22*5% -> 97.5 | CY22: =CW22-CX22 -> 1852.5 | DH22: ='Billable Till Date'!B18 & "-" & 'Billable Till Date'!C18 -> Task/Activity-Unit Type
B23: Ramakanth | C23: Barbender Helper | D23: Labour-017 | E23: Siva Prasad | F23: 8 | G23: 0 | H23: 8 | I23: 2 | J23: 8 | K23: 2 | L23: 8 | M23: 2 | N23: 8 | O23: 2 | R23: =SUM(F23,H23,J23,L23,N23,P23) -> 40 | S23: =SUM(G23,I23,K23,M23,O23,Q23) -> 8 | T23: =IFERROR(INDEX(Settings!$F:$F, MATCH('PROJECT NAME NOV'!$B23 & "-" & 'PROJECT NAME NOV'!$C23, Settings!$H:$H,0)), "") -> 81.25 | U23: =IFERROR(INDEX(Settings!$G:$G, MATCH('PROJECT NAME NOV'!$B23 & "-" & 'PROJECT NAME NOV'!$C23, Settings!$H:$H, 0)), "") -> 650 | V23: =(R23*T23)+(S23*T23) -> 3900 | W23: =V23*5% -> 195 | X23: =V23-W23 -> 3705 | Y23: 8 | Z23: 0 | AA23: 8 | AB23: 2 | AC23: 8 | AD23: 0 | AE23: 8 | AF23: 2 | AG23: 8 | AH23: 2 | AI23: 8 | AJ23: 2 | AK23: 8 | AL23: 2 | AM23: =IFERROR(INDEX(Settings!$F:$F, MATCH('PROJECT NAME NOV'!$B23 & "-" & 'PROJECT NAME NOV'!$C23, Settings!$H:$H,0)), "") -> 81.25 | AN23: =IFERROR(INDEX(Settings!$G:$G, MATCH('PROJECT NAME NOV'!$B23 & "-" & 'PROJECT NAME NOV'!$C23, Settings!$H:$H, 0)), "") -> 650 | AO23: =SUM(Y23,AA23,AC23,AE23,AG23,AI23,AK23) -> 56 | AP23: =SUM(Z23,AB23,AD23,AF23,AH23,AJ23,AL23) -> 10 | AQ23: =(AO23*AM23)+(AP23*AM23) -> 5362.5 | AR23: =AQ23*5% -> 268.125 | AS23: =AQ23-AR23 -> 5094.375 | AU23: 8 | AV23: 0 | AW23: 8 | AX23: 0 | AY23: 8 | AZ23: 0 | BA23: 8 | BB23: 4 | BC23: 8 | BD23: 4 | BE23: 8 | BF23: 0 | BG23: 8 | BH23: 4 | BI23: =SUM(AU23,AW23,AY23,BA23,BC23,BE23,BG23) -> 56 | BJ23: =SUM(AV23,AX23,AZ23,BB23,BD23,BF23,BH23) -> 12 | BK23: =IFERROR(INDEX(Settings!$F:$F, MATCH('PROJECT NAME NOV'!$B23 & "-" & 'PROJECT NAME NOV'!$C23, Settings!$H:$H,0)), "") -> 81.25 | BL23: =IFERROR(INDEX(Settings!$G:$G, MATCH('PROJECT NAME NOV'!$B23 & "-" & 'PROJECT NAME NOV'!$C23, Settings!$H:$H, 0)), "") -> 650 | BM23: =(BI23*BK23)+(BJ23*BK23) -> 5525 | BN23: =BM23*5% -> 276.25 | BO23: =BM23-BN23 -> 5248.75 | BQ23: 8 | BR23: 2 | BS23: 8 | BT23: 2 | BU23: 8 | BV23: 0 | BW23: 8 | BX23: 2 | BY23: 8 | BZ23: 2 | CA23: 8 | CB23: 2 | CC23: 8 | CE23: =SUM(BQ23,BS23,BU23,BW23,BY23,CA23,CC23) -> 56 | CF23: =SUM(BR23,BT23,BV23,BX23,BZ23,CB23,CD23) -> 10 | CG23: =IFERROR(INDEX(Settings!$F:$F, MATCH('PROJECT NAME NOV'!$B23 & "-" & 'PROJECT NAME NOV'!$C23, Settings!$H:$H,0)), "") -> 81.25 | CH23: =IFERROR(INDEX(Settings!$G:$G, MATCH('PROJECT NAME NOV'!$B23 & "-" & 'PROJECT NAME NOV'!$C23, Settings!$H:$H, 0)), "") -> 650 | CI23: =(CE23*CG23)+(CF23*CG23) -> 5362.5 | CJ23: =CI23*5% -> 268.125 | CK23: =CI23-CJ23 -> 5094.375 | CM23: 8 | CN23: 4 | CO23: 8 | CP23: 4 | CS23: =SUM(CM23,CO23,CQ23) -> 16 | CT23: =SUM(CN23,CP23,CR23) -> 8 | CU23: =IFERROR(INDEX(Settings!$F:$F, MATCH('PROJECT NAME NOV'!$B23 & "-" & 'PROJECT NAME NOV'!$C23, Settings!$H:$H,0)), "") -> 81.25 | CV23: =IFERROR(INDEX(Settings!$G:$G, MATCH('PROJECT NAME NOV'!$B23 & "-" & 'PROJECT NAME NOV'!$C23, Settings!$H:$H, 0)), "") -> 650 | CW23: =(CU23*CS23)+(CT23*CU23) -> 1950 | CX23: =CW23*5% -> 97.5 | CY23: =CW23-CX23 -> 1852.5 | DH23: ='Billable Till Date'!B19 & "-" & 'Billable Till Date'!C19 -> Task/Activity-Unit Type
B24: Ramakanth | C24: Barbender Helper | D24: Labour-018 | E24: Ravilal | F24: 8 | G24: 0 | H24: 8 | I24: 2 | J24: 8 | K24: 2 | L24: 8 | M24: 2 | N24: 8 | O24: 2 | R24: =SUM(F24,H24,J24,L24,N24,P24) -> 40 | S24: =SUM(G24,I24,K24,M24,O24,Q24) -> 8 | T24: =IFERROR(INDEX(Settings!$F:$F, MATCH('PROJECT NAME NOV'!$B24 & "-" & 'PROJECT NAME NOV'!$C24, Settings!$H:$H,0)), "") -> 81.25 | U24: =IFERROR(INDEX(Settings!$G:$G, MATCH('PROJECT NAME NOV'!$B24 & "-" & 'PROJECT NAME NOV'!$C24, Settings!$H:$H, 0)), "") -> 650 | V24: =(R24*T24)+(S24*T24) -> 3900 | W24: =V24*5% -> 195 | X24: =V24-W24 -> 3705 | Y24: 8 | Z24: 0 | AA24: 8 | AB24: 2 | AC24: 8 | AD24: 0 | AE24: 8 | AF24: 2 | AG24: 8 | AH24: 2 | AI24: 8 | AJ24: 2 | AK24: 8 | AL24: 2 | AM24: =IFERROR(INDEX(Settings!$F:$F, MATCH('PROJECT NAME NOV'!$B24 & "-" & 'PROJECT NAME NOV'!$C24, Settings!$H:$H,0)), "") -> 81.25 | AN24: =IFERROR(INDEX(Settings!$G:$G, MATCH('PROJECT NAME NOV'!$B24 & "-" & 'PROJECT NAME NOV'!$C24, Settings!$H:$H, 0)), "") -> 650 | AO24: =SUM(Y24,AA24,AC24,AE24,AG24,AI24,AK24) -> 56 | AP24: =SUM(Z24,AB24,AD24,AF24,AH24,AJ24,AL24) -> 10 | AQ24: =(AO24*AM24)+(AP24*AM24) -> 5362.5 | AR24: =AQ24*5% -> 268.125 | AS24: =AQ24-AR24 -> 5094.375 | AU24: 8 | AV24: 0 | AW24: 8 | AX24: 4 | AY24: 8 | AZ24: 0 | BA24: 8 | BB24: 4 | BC24: 8 | BD24: 4 | BE24: 8 | BF24: 0 | BG24: 8 | BH24: 4 | BI24: =SUM(AU24,AW24,AY24,BA24,BC24,BE24,BG24) -> 56 | BJ24: =SUM(AV24,AX24,AZ24,BB24,BD24,BF24,BH24) -> 16 | BK24: =IFERROR(INDEX(Settings!$F:$F, MATCH('PROJECT NAME NOV'!$B24 & "-" & 'PROJECT NAME NOV'!$C24, Settings!$H:$H,0)), "") -> 81.25 | BL24: =IFERROR(INDEX(Settings!$G:$G, MATCH('PROJECT NAME NOV'!$B24 & "-" & 'PROJECT NAME NOV'!$C24, Settings!$H:$H, 0)), "") -> 650 | BM24: =(BI24*BK24)+(BJ24*BK24) -> 5850 | BN24: =BM24*5% -> 292.5 | BO24: =BM24-BN24 -> 5557.5 | BQ24: 8 | BR24: 2 | BS24: 8 | BT24: 2 | BU24: 8 | BV24: 0 | BW24: 8 | BX24: 2 | BY24: 8 | BZ24: 2 | CA24: 8 | CB24: 2 | CC24: 8 | CE24: =SUM(BQ24,BS24,BU24,BW24,BY24,CA24,CC24) -> 56 | CF24: =SUM(BR24,BT24,BV24,BX24,BZ24,CB24,CD24) -> 10 | CG24: =IFERROR(INDEX(Settings!$F:$F, MATCH('PROJECT NAME NOV'!$B24 & "-" & 'PROJECT NAME NOV'!$C24, Settings!$H:$H,0)), "") -> 81.25 | CH24: =IFERROR(INDEX(Settings!$G:$G, MATCH('PROJECT NAME NOV'!$B24 & "-" & 'PROJECT NAME NOV'!$C24, Settings!$H:$H, 0)), "") -> 650 | CI24: =(CE24*CG24)+(CF24*CG24) -> 5362.5 | CJ24: =CI24*5% -> 268.125 | CK24: =CI24-CJ24 -> 5094.375 | CM24: 8 | CN24: 4 | CO24: 8 | CP24: 4 | CS24: =SUM(CM24,CO24,CQ24) -> 16 | CT24: =SUM(CN24,CP24,CR24) -> 8 | CU24: =IFERROR(INDEX(Settings!$F:$F, MATCH('PROJECT NAME NOV'!$B24 & "-" & 'PROJECT NAME NOV'!$C24, Settings!$H:$H,0)), "") -> 81.25 | CV24: =IFERROR(INDEX(Settings!$G:$G, MATCH('PROJECT NAME NOV'!$B24 & "-" & 'PROJECT NAME NOV'!$C24, Settings!$H:$H, 0)), "") -> 650 | CW24: =(CU24*CS24)+(CT24*CU24) -> 1950 | CX24: =CW24*5% -> 97.5 | CY24: =CW24-CX24 -> 1852.5 | DH24: ='Billable Till Date'!B20 & "-" & 'Billable Till Date'!C20 -> Task/Activity-Unit Type
B25: Ramakanth | C25: Barbender Helper | D25: Labour-019 | E25: Narendar | F25: 8 | G25: 0 | H25: 8 | I25: 2 | J25: 8 | K25: 2 | L25: 0 | M25: 0 | N25: 8 | O25: 2 | R25: =SUM(F25,H25,J25,L25,N25,P25) -> 32 | S25: =SUM(G25,I25,K25,M25,O25,Q25) -> 6 | T25: =IFERROR(INDEX(Settings!$F:$F, MATCH('PROJECT NAME NOV'!$B25 & "-" & 'PROJECT NAME NOV'!$C25, Settings!$H:$H,0)), "") -> 81.25 | U25: =IFERROR(INDEX(Settings!$G:$G, MATCH('PROJECT NAME NOV'!$B25 & "-" & 'PROJECT NAME NOV'!$C25, Settings!$H:$H, 0)), "") -> 650 | V25: =(R25*T25)+(S25*T25) -> 3087.5 | W25: =V25*5% -> 154.375 | X25: =V25-W25 -> 2933.125 | Y25: 8 | Z25: 0 | AA25: 8 | AB25: 2 | AC25: 8 | AD25: 0 | AE25: 8 | AF25: 2 | AG25: 8 | AH25: 2 | AI25: 0 | AJ25: 0 | AK25: 8 | AL25: 2 | AM25: =IFERROR(INDEX(Settings!$F:$F, MATCH('PROJECT NAME NOV'!$B25 & "-" & 'PROJECT NAME NOV'!$C25, Settings!$H:$H,0)), "") -> 81.25 | AN25: =IFERROR(INDEX(Settings!$G:$G, MATCH('PROJECT NAME NOV'!$B25 & "-" & 'PROJECT NAME NOV'!$C25, Settings!$H:$H, 0)), "") -> 650 | AO25: =SUM(Y25,AA25,AC25,AE25,AG25,AI25,AK25) -> 48 | AP25: =SUM(Z25,AB25,AD25,AF25,AH25,AJ25,AL25) -> 8 | AQ25: =(AO25*AM25)+(AP25*AM25) -> 4550 | AR25: =AQ25*5% -> 227.5 | AS25: =AQ25-AR25 -> 4322.5 | AU25: 8 | AV25: 2 | AW25: 8 | AX25: 4 | AY25: 8 | AZ25: 0 | BA25: 8 | BB25: 4 | BC25: 8 | BD25: 4 | BE25: 8 | BF25: 0 | BG25: 8 | BH25: 4 | BI25: =SUM(AU25,AW25,AY25,BA25,BC25,BE25,BG25) -> 56 | BJ25: =SUM(AV25,AX25,AZ25,BB25,BD25,BF25,BH25) -> 18 | BK25: =IFERROR(INDEX(Settings!$F:$F, MATCH('PROJECT NAME NOV'!$B25 & "-" & 'PROJECT NAME NOV'!$C25, Settings!$H:$H,0)), "") -> 81.25 | BL25: =IFERROR(INDEX(Settings!$G:$G, MATCH('PROJECT NAME NOV'!$B25 & "-" & 'PROJECT NAME NOV'!$C25, Settings!$H:$H, 0)), "") -> 650 | BM25: =(BI25*BK25)+(BJ25*BK25) -> 6012.5 | BN25: =BM25*5% -> 300.625 | BO25: =BM25-BN25 -> 5711.875 | BQ25: 8 | BR25: 2 | BS25: 8 | BT25: 2 | BU25: 8 | BV25: 0 | BW25: 8 | BX25: 2 | BY25: 8 | BZ25: 2 | CA25: 8 | CB25: 2 | CC25: 8 | CE25: =SUM(BQ25,BS25,BU25,BW25,BY25,CA25,CC25) -> 56 | CF25: =SUM(BR25,BT25,BV25,BX25,BZ25,CB25,CD25) -> 10 | CG25: =IFERROR(INDEX(Settings!$F:$F, MATCH('PROJECT NAME NOV'!$B25 & "-" & 'PROJECT NAME NOV'!$C25, Settings!$H:$H,0)), "") -> 81.25 | CH25: =IFERROR(INDEX(Settings!$G:$G, MATCH('PROJECT NAME NOV'!$B25 & "-" & 'PROJECT NAME NOV'!$C25, Settings!$H:$H, 0)), "") -> 650 | CI25: =(CE25*CG25)+(CF25*CG25) -> 5362.5 | CJ25: =CI25*5% -> 268.125 | CK25: =CI25-CJ25 -> 5094.375 | CS25: =SUM(CM25,CO25,CQ25) -> 0 | CT25: =SUM(CN25,CP25,CR25) -> 0 | CU25: =IFERROR(INDEX(Settings!$F:$F, MATCH('PROJECT NAME NOV'!$B25 & "-" & 'PROJECT NAME NOV'!$C25, Settings!$H:$H,0)), "") -> 81.25 | CV25: =IFERROR(INDEX(Settings!$G:$G, MATCH('PROJECT NAME NOV'!$B25 & "-" & 'PROJECT NAME NOV'!$C25, Settings!$H:$H, 0)), "") -> 650 | CW25: =(CU25*CS25)+(CT25*CU25) -> 0 | CX25: =CW25*5% -> 0 | CY25: =CW25-CX25 -> 0 | DH25: ='Billable Till Date'!B21 & "-" & 'Billable Till Date'!C21 -> -
